Workbook
Name __Complete_Materials: Materials!$M$12
Name __Variance_Materials: Materials!$O$12
Name _Change_Order_Labor_Dollar_Est___Labor_Projection: 'Labor Projection'!$P$12
Name _Current_Labor_Dollar_Estimate__Labor_Projection: 'Labor Projection'!$Q$12
Name _Current_Labor_Dollar_Estimate__NTPLH: 'Labor Projection'!$Q$16
Name _Est____Hour__Labor_Projection: 'Labor Projection'!$V$12
Name _Est__Total_Labor__Labor_Projection: 'Labor Projection'!$T$12
Name _Est__Total_Labor__NTPLH: 'Labor Projection'!$T$16
Name _Est_Labor_to_Complete_Labor_Projection: 'Labor Projection'!$S$12
Name _Est_Labor_to_Complete_NTPLH: 'Labor Projection'!$S$16
Name _JTD____Hr__Labor_Projection: 'Labor Projection'!$W$12
Name _JTD_Labor_Cost__Labor_Projection: 'Labor Projection'!$R$12
Name _JTD_Labor_Cost__NTPLH: 'Labor Projection'!$R$16
Name _Original_Labor_Dollar_Est___Labor_Projection: 'Labor Projection'!$O$12
Name _TOTAL_LABOR_HOURS__ContractStatus: #REF!
Name _Under____Over____Labor_Projection: 'Labor Projection'!$X$12
Name _Under____Over___Labor_Projection: 'Labor Projection'!$U$12
Name _Under____Over__Labor_Projection: 'Labor Projection'!$N$12
Name _Under__Over_NTPLH: 'Labor Projection'!$U$16
Name ABC_NTPLH: 'Labor Projection'!$B$16
Name Actual_Composite_rate_dashboard: Sheet7!$V$5
Name Actual_Gross_Margin_dashboard: Sheet7!$J$5
Name Actual_Manhour_dashboard: Sheet7!$I$5
Name AR_Aged_Current_dashboard: Sheet7!$X$5
Name ARAged130days_dashboard: Sheet7!$Y$5
Name ARAged3160days_dashboard: Sheet7!$Z$5
Name ARAged6190days_dashboard: Sheet7!$AA$5
Name ARAgedover90days_dashboard: Sheet7!$AB$5
Name Base_Hrs_to_Complete_Labor_Projection: 'Labor Projection'!$I$12
Name Base_Hrs_to_Complete_NTPLH: 'Labor Projection'!$I$16
Name bid_day_Labor_Performance_Factor_dashboard: Sheet7!$M$5
Name Bid_day_Labor_Performance_Factor_Labor_Performance: 'Labor Performance'!$F$3
Name Change_Order_Hours_Estimate_Labor_Projection: 'Labor Projection'!$E$12
Name Change_Order_Hours_Estimate_NTPLH: 'Labor Projection'!$E$16
Name Change_Order_Labor_Dollar_Est__NTPLH: 'Labor Projection'!$P$16
Name Change_Orders_Estimate_Materials: Materials!$F$12
Name CO_Date_ContractStatus: #REF!
Name Composite_Rate_ContractStatus: #REF!
Name Composite_Rate_Variance_dashboard: Sheet7!$W$5
Name Cost_Type_Labor_Projection: 'Labor Projection'!$C$12
Name Cost_Type_Materials: Materials!$B$12
Name CostType1_Materials: Materials!$C$12
Name Current_Estimate_Materials: Materials!$G$12
Name Current_Labor_Hours_Estimate_Labor_Projection: 'Labor Projection'!$F$12
Name Current_Labor_Hours_Estimate_NTPLH: 'Labor Projection'!$F$16
Name Current_Labor_Performance_Factor_dashboard: Sheet7!$H$5
Name Department_dashboard: Sheet7!$C$5
Name Description_ContractStatus: #REF!
Name EOPeriodDate_dashboard: Sheet7!$E$5
Name EOPeriodDate_Labor_Performance: 'Labor Performance'!$C$3
Name Est____Complete_Labor_Projection: 'Labor Projection'!$H$12
Name Est____Complete_NTPLH: 'Labor Projection'!$H$16
Name Est____Hour_NTPLH: 'Labor Projection'!$V$16
Name Est_CompleteATYE_dashboard: Sheet7!$N$5
Name Estimated___Complete___YE_Block26: Summary!$J$42
Name Estimated___Complete___YE_Block28: Summary!$J$42
Name Estimated_Composite_Rate_dashboard: Sheet7!$U$5
Name Estimated_Future_Costs_Materials: Materials!$K$12
Name Estimated_Gross_Margin_dashboard: Sheet7!$G$5
Name Estimated_Manhours_dashboard: Sheet7!$F$5

Sheet Query
A1: WITH
A2: subqueryTable0 AS (
A3: SELECT DISTINCT
A4: table0.Company_Code AS Company_Code,
A5: table0.Job_Number AS Job_Number,
A6: table0.Phase_Code AS Phase_Code,
A7: table0.Cost_Type AS Cost_Type,
A8: table0.Description AS Description,
A9: table0.Phase_Job_Number AS Phase_Job_Number,
A10: table0.Cost_Center AS Cost_Center,
A11: table0.Status_Code AS Status_Code
A12: FROM
... A593: AND maintable.Phase_Job_Number = subqueryTable25.Job_Number)

Sheet Summary
H1: Job Name | J1: JOINT RESERVE BASE HANGAR
H9: Job No. | J9: 643700
H10: Project Manager | J10: J RAMOS
H11: Report Date | J11: 2026-01-07
H12: As of Date
F15: Revised Contract | G15: Notice to Proceed | H15: Pending | I15: Pending Contract | J15: Projected | K15: Variance | L15: Prior Month Variance
A16: Revenue | F16: {=#REF!} -> #REF! | G16: {=#REF!} -> #REF! | H16: {=#REF!} -> #REF! | I16: =F16+G16 -> #REF! | J16: {=#REF!} -> #REF! | K16: =ROUND(J16-I16,2) -> #REF! | L16: =DATA!B8-J16 -> #REF!
A18: Labor | F18: {=#REF!} -> #REF! | G18: {=#REF!} -> #REF! | H18: {=#REF!} -> #REF! | I18: =F18+G18 -> #REF! | J18: {='Labor Projection'!T10} -> 0 | K18: =ROUND(J18-I18,2) -> #REF! | L18: =DATA!C8-J18 -> 0
A19: Burden | F19: {=#REF!} -> #REF! | G19: {=#REF!} -> #REF! | H19: {=#REF!} -> #REF! | I19: =F19+G19 -> #REF! | J19: =('Labor Projection'!I10*'Labor Projection'!N1)+'Manpower Projection'!J16 -> #DIV/0! | K19: =ROUND(J19-I19,2) -> #DIV/0! | L19: =DATA!D8-J19 -> #DIV/0!
A20: Material / Subcontracts | F20: {=#REF!} -> #REF! | G20: {=#REF!} -> #REF! | H20: {=#REF!} -> #REF! | I20: =F20+G20 -> #REF! | J20: {=Materials!L3} -> 473279.63 | K20: =ROUND(J20-I20,2) -> #REF! | L20: =DATA!E8-J20 -> -473279.63
A21: DJE / Other | F21: {=#REF!} -> #REF! | G21: {=#REF!} -> #REF! | H21: {=#REF!} -> #REF! | I21: =F21+G21 -> #REF! | J21: {=Materials!L4} -> 29087.91 | K21: =ROUND(J21-I21,2) -> #REF! | L21: =DATA!F8-J21 -> -29087.91
A22: Total Cost | F22: =SUM(F18:F21) -> #REF! | G22: =SUM(G18:G21) -> #REF! | H22: =SUM(H18:H21) -> #REF! | I22: =SUM(I18:I21) -> #REF! | J22: =SUM(J18:J21) -> #DIV/0! | K22: =SUM(K18:K21) -> #REF! | L22: =SUM(L18:L21)-J22 -> #DIV/0!
A24: Profit | F24: =F16-F22 -> #REF! | G24: =G16-G22 -> #REF! | H24: =H16-H22 -> #REF! | I24: =I16-I22 -> #REF! | J24: =J16-J22 -> #REF! | K24: =K16-K22 -> #REF! | L24: =DATA!B8-SUM(DATA!C8:F8)-J24 -> #REF!
A25: Profit % on Cost | F25: =F24/F22 -> #REF! | G25: =G24/G22 -> #REF! | H25: =H24/H22 -> #REF! | I25: =I24/I22 -> #REF! | J25: =J24/J22 -> #REF! | K25: =ROUND(Summary!J25-Summary!I25,2) -> #REF! | L25: =DATA!G8-J25 -> #REF!
A26: Profit % on Rev | F26: =IF(F16=0,0,F24/F16) -> #REF! | G26: =IF(G16=0,0,G24/G16) -> #REF! | H26: =IF(H16=0,0,H24/H16) -> #REF! | I26: =ROUND(IF(I16=0,0,I24/I16),2) -> #REF! | J26: =ROUND(IF(J16=0,0,J24/J16),2) -> #REF! | K26: =IF(K16=0,0,K24/K16) -> #REF! | L26: =IF(L16=0,0,L24/L16) -> #REF!
A28: FINANCIAL AND OPERATIONAL DASHBOARD FOR THIS REPORTING PERIOD
A29: Over/ (Under) Billings | I29: Project Cash to Cost Position
A30: JTD Gross Billings $ | F30: None | I30: JTD Collected $ | J30: None
A31: JTD Revenue $ | F31: None | I31: JTD Cost $ | J31: =Materials!H10+'Manpower Projection'!K16 -> 24375.4
A32: Over/ (Under) Billing $ | F32: =F30-F31 -> #VALUE! | I32: Net Cash Position $ | J32: =J30-J31 -> #VALUE!
A33: As of Date: | F33: 2025-12-31 | I33: As of Date: | J33: 2025-12-31
A35: Composite Rate Analysis | I35: Labor Performance Factor | L35: Prior Month
A36: Composite Rate (Est.) | F36: =ROUND(#REF!,2) -> #REF! | I36: Earned MH's | J36: =ROUND('Labor Projection'!F10*'Labor Projection'!H10,2) -> #REF! | K36: =J36*F36 -> #REF! | L36: =J36-DATA!H8 -> #REF! | M36: =K36-(DATA!J8*DATA!H8) -> #REF!
A37: Composite Rate (Act.) | F37: =ROUND('Labor Projection'!R10/'Labor Projection'!G10,2) -> 51.69 | I37: Actual MH's | J37: =ROUND('Labor Projection'!G10,2) -> 290 | K37: =J37*F37 -> 14990.1 | L37: =J37-DATA!I8 -> 290 | M37: =K37-(DATA!K8*DATA!I8) -> 14990.1
A38: Composite Rate Var | F38: =F36-F37 -> #REF! | I38: Labor Performance Factor | J38: =J36/J37 -> #REF! | K38: =K36/K37 -> #REF! | L38: =L36/L37 -> #REF! | M38: =M36/M37 -> #REF!
A39: As of Date: | F39: 2025-12-31 | I39: As of Date: | J39: 2025-12-31
A41: A/R Aged Open Items | I41: Estimated % Complete @ YE value | J41: 0.03
A42: Current | F42: None
A43: 1-30 Days | F43: None | I43: Bid day Labor Performance Factor
A44: 31-60 Days | F44: None
A45: 61-90 Days | F45: None
A46: Over 90 Days | F46: None
A47: Last Billing Date | F47: NaT
A49: NOTES REGARDING SCHEDULE, JOB PROGRESS, CONCERNS:

Sheet Manpower Projection
F1: JOINT RESERVE BASE HANGAR
M3: Burden Cost | N3: Labor Cost | O3: Total Hours
J4: 9240.130000000 | M4: =SUM(#REF!) -> #REF! | N4: =SUM(#REF!) -> #REF! | O4: =SUM(#REF!) -> #REF!
F10: Projection Labor & Burden
F12: Job Projection
F13: Projection Labor Rate | I13: =I17/H17 -> #DIV/0!
F14: Projection L&B Rate | I14: =(I17+J17)/H17 -> #DIV/0!
F15: Week Ending: | H15: Total Hrs | I15: Labor Cost | J15: Burden Cost | K15: Total Cost | L15: Labor / Hr | M15: L&B / Hr
F16: Job to Date | H16: {=IF('Manpower Projection'!J4="None",'Manpower Projection'!O4,'Labor Projection'!G10)} -> 290 | I16: {=IF('Manpower Projection'!J4="None",'Manpower Projection'!N4,'Labor Projection'!R10)} -> 14989.17 | J16: =IF('Manpower Projection'!J4="None",'Manpower Projection'!M4,'Manpower Projection'!J4) -> 9240.130000000 | K16: =I16+J16 -> 24229.3 | L16: =ROUND(I16/H16,2) -> 51.69 | M16: =K16/H16 -> 83.54931
F17: Projection to Complete | H17: {=K25} -> 0 | I17: =H17*N25 -> 0 | J17: =(H17*O25)-I17 -> 0 | K17: =H17*I14 -> #DIV/0! | L17: =I17/H17 -> #DIV/0! | M17: =K17/H17 -> #DIV/0!
F19: Total Projection | H19: =H16+H17 -> 290 | I19: =I16+I17 -> 14989.17 | J19: =J16+J17 -> 9240.13 | K19: =K16+K17 -> #DIV/0! | L19: =I19/H19 -> 51.686793 | M19: =K19/H19 -> #DIV/0!
F20: Bid + Change Orders | H20: =#REF! -> #REF! | I20: =#REF! -> #REF! | J20: =#REF! -> #REF! | K20: =I20+J20 -> #REF! | L20: =I20/H20 -> #REF! | M20: =K20/H20 -> #REF! | O20: ='Manpower Projection'!H16 -> 290
F21: Variance | H21: =H19-H20 -> #REF! | I21: =I19-I20 -> #REF! | J21: =J19-J20 -> #REF! | K21: =K19-K20 -> #DIV/0! | L21: =L19-L20 -> #REF! | M21: =M19-M20 -> #DIV/0!
H24: Average Crew | I24: Ave Hrs | J24: Ave Days | K24: Total Hrs | L24: Labor Projection | M24: Delta | N24: Avg Composite Rate | O24: Avg L&B Rate
F25: Manpower Projection | H25: =AVERAGE('Manpower Projection'!H29:H5000) -> 4.5454545 | I25: =AVERAGE('Manpower Projection'!I29:I5000) -> 10 | J25: =AVERAGE('Manpower Projection'!J29:J5000) -> 4 | K25: =SUMIF('Manpower Projection'!G29:G5000,"",'Manpower Projection'!K29:K5000) -> 0 | L25: ='Labor Projection'!L10 -> 12624.476 | M25: =K25-L25 -> -12624.476 | N25: =N27/H27 -> 51.69 | O25: =O27/H27 -> 83.54931
F27: Grand Total | G27: - | H27: =SUBTOTAL(9,H29:H528) -> 50 | I27: =SUBTOTAL(9,I29:I528) -> 110 | J27: =SUBTOTAL(9,J29:J528) -> 44 | K27: =SUBTOTAL(9,K29:K528) -> 2000 | L27: - | M27: - | N27: =SUBTOTAL(9,N29:N528) -> 2584.5 | O27: =SUBTOTAL(9,O29:O528) -> 4177.4655
F28: Week ending: | G28: Actual Manpower | H28: Estimated Manpower | I28: Hours/Day | J28: Days/Week | K28: Total Hours | L28: Composite Rate | M28: L&B Rate | N28: Avg Composite Rate | O28: Avg L&B Rate
F29: 45968 | K29: =IFERROR('Manpower Projection'!H29*'Manpower Projection'!I29*'Manpower Projection'!J29,0) -> 0 | L29: {='Manpower Projection'!$L$16} -> 51.69 | M29: ='Manpower Projection'!$M$16 -> 83.54931 | N29: =IFERROR('Manpower Projection'!H29*'Manpower Projection'!L29,"") -> 0 | O29: =IFERROR('Manpower Projection'!M29*'Manpower Projection'!H29,"") -> 0
F30: 45975 | K30: =IFERROR('Manpower Projection'!H30*'Manpower Projection'!I30*'Manpower Projection'!J30,0) -> 0 | L30: {='Manpower Projection'!$L$16} -> 51.69 | M30: ='Manpower Projection'!$M$16 -> 83.54931 | N30: =IFERROR('Manpower Projection'!H30*'Manpower Projection'!L30,"") -> 0 | O30: =IFERROR('Manpower Projection'!M30*'Manpower Projection'!H30,"") -> 0
F31: 45982 | K31: =IFERROR('Manpower Projection'!H31*'Manpower Projection'!I31*'Manpower Projection'!J31,0) -> 0 | L31: {='Manpower Projection'!$L$16} -> 51.69 | M31: ='Manpower Projection'!$M$16 -> 83.54931 | N31: =IFERROR('Manpower Projection'!H31*'Manpower Projection'!L31,"") -> 0 | O31: =IFERROR('Manpower Projection'!M31*'Manpower Projection'!H31,"") -> 0
F32: 45989 | G32: 2 | H32: 2 | I32: 10 | J32: 4 | K32: =IFERROR('Manpower Projection'!H32*'Manpower Projection'!I32*'Manpower Projection'!J32,0) -> 80 | L32: {='Manpower Projection'!$L$16} -> 51.69 | M32: ='Manpower Projection'!$M$16 -> 83.54931 | N32: =IFERROR('Manpower Projection'!H32*'Manpower Projection'!L32,"") -> 103.38 | O32: =IFERROR('Manpower Projection'!M32*'Manpower Projection'!H32,"") -> 167.09862
F33: 45996 | G33: 2 | H33: 2 | I33: 10 | J33: 4 | K33: =IFERROR('Manpower Projection'!H33*'Manpower Projection'!I33*'Manpower Projection'!J33,0) -> 80 | L33: {='Manpower Projection'!$L$16} -> 51.69 | M33: ='Manpower Projection'!$M$16 -> 83.54931 | N33: =IFERROR('Manpower Projection'!H33*'Manpower Projection'!L33,"") -> 103.38 | O33: =IFERROR('Manpower Projection'!M33*'Manpower Projection'!H33,"") -> 167.09862
F34: 46003 | G34: 2 | H34: 2 | I34: 10 | J34: 4 | K34: =IFERROR('Manpower Projection'!H34*'Manpower Projection'!I34*'Manpower Projection'!J34,0) -> 80 | L34: {='Manpower Projection'!$L$16} -> 51.69 | M34: ='Manpower Projection'!$M$16 -> 83.54931 | N34: =IFERROR('Manpower Projection'!H34*'Manpower Projection'!L34,"") -> 103.38 | O34: =IFERROR('Manpower Projection'!M34*'Manpower Projection'!H34,"") -> 167.09862
F35: 46010 | G35: 2 | H35: 2 | I35: 10 | J35: 4 | K35: =IFERROR('Manpower Projection'!H35*'Manpower Projection'!I35*'Manpower Projection'!J35,0) -> 80 | L35: {='Manpower Projection'!$L$16} -> 51.69 | M35: ='Manpower Projection'!$M$16 -> 83.54931 | N35: =IFERROR('Manpower Projection'!H35*'Manpower Projection'!L35,"") -> 103.38 | O35: =IFERROR('Manpower Projection'!M35*'Manpower Projection'!H35,"") -> 167.09862
F36: 46017 | G36: 6 | H36: 6 | I36: 10 | J36: 4 | K36: =IFERROR('Manpower Projection'!H36*'Manpower Projection'!I36*'Manpower Projection'!J36,0) -> 240 | L36: {='Manpower Projection'!$L$16} -> 51.69 | M36: ='Manpower Projection'!$M$16 -> 83.54931 | N36: =IFERROR('Manpower Projection'!H36*'Manpower Projection'!L36,"") -> 310.14 | O36: =IFERROR('Manpower Projection'!M36*'Manpower Projection'!H36,"") -> 501.29586
F37: 46024 | G37: 6 | H37: 6 | I37: 10 | J37: 4 | K37: =IFERROR('Manpower Projection'!H37*'Manpower Projection'!I37*'Manpower Projection'!J37,0) -> 240 | L37: {='Manpower Projection'!$L$16} -> 51.69 | M37: ='Manpower Projection'!$M$16 -> 83.54931 | N37: =IFERROR('Manpower Projection'!H37*'Manpower Projection'!L37,"") -> 310.14 | O37: =IFERROR('Manpower Projection'!M37*'Manpower Projection'!H37,"") -> 501.29586
F38: 46031 | G38: 6 | H38: 6 | I38: 10 | J38: 4 | K38: =IFERROR('Manpower Projection'!H38*'Manpower Projection'!I38*'Manpower Projection'!J38,0) -> 240 | L38: {='Manpower Projection'!$L$16} -> 51.69 | M38: ='Manpower Projection'!$M$16 -> 83.54931 | N38: =IFERROR('Manpower Projection'!H38*'Manpower Projection'!L38,"") -> 310.14 | O38: =IFERROR('Manpower Projection'!M38*'Manpower Projection'!H38,"") -> 501.29586
F39: 46038 | G39: 6 | H39: 6 | I39: 10 | J39: 4 | K39: =IFERROR('Manpower Projection'!H39*'Manpower Projection'!I39*'Manpower Projection'!J39,0) -> 240 | L39: {='Manpower Projection'!$L$16} -> 51.69 | M39: ='Manpower Projection'!$M$16 -> 83.54931 | N39: =IFERROR('Manpower Projection'!H39*'Manpower Projection'!L39,"") -> 310.14 | O39: =IFERROR('Manpower Projection'!M39*'Manpower Projection'!H39,"") -> 501.29586
F40: 46045 | G40: 6 | H40: 6 | I40: 10 | J40: 4 | K40: =IFERROR('Manpower Projection'!H40*'Manpower Projection'!I40*'Manpower Projection'!J40,0) -> 240 | L40: {='Manpower Projection'!$L$16} -> 51.69 | M40: ='Manpower Projection'!$M$16 -> 83.54931 | N40: =IFERROR('Manpower Projection'!H40*'Manpower Projection'!L40,"") -> 310.14 | O40: =IFERROR('Manpower Projection'!M40*'Manpower Projection'!H40,"") -> 501.29586
F41: 46052 | G41: 6 | H41: 6 | I41: 10 | J41: 4 | K41: =IFERROR('Manpower Projection'!H41*'Manpower Projection'!I41*'Manpower Projection'!J41,0) -> 240 | L41: {='Manpower Projection'!$L$16} -> 51.69 | M41: ='Manpower Projection'!$M$16 -> 83.54931 | N41: =IFERROR('Manpower Projection'!H41*'Manpower Projection'!L41,"") -> 310.14 | O41: =IFERROR('Manpower Projection'!M41*'Manpower Projection'!H41,"") -> 501.29586
F42: 46059 | G42: 6 | H42: 6 | I42: 10 | J42: 4 | K42: =IFERROR('Manpower Projection'!H42*'Manpower Projection'!I42*'Manpower Projection'!J42,0) -> 240 | L42: {='Manpower Projection'!$L$16} -> 51.69 | M42: ='Manpower Projection'!$M$16 -> 83.54931 | N42: =IFERROR('Manpower Projection'!H42*'Manpower Projection'!L42,"") -> 310.14 | O42: =IFERROR('Manpower Projection'!M42*'Manpower Projection'!H42,"") -> 501.29586
F43: 46066 | K43: =IFERROR('Manpower Projection'!H43*'Manpower Projection'!I43*'Manpower Projection'!J43,0) -> 0 | L43: {='Manpower Projection'!$L$16} -> 51.69 | M43: ='Manpower Projection'!$M$16 -> 83.54931 | N43: =IFERROR('Manpower Projection'!H43*'Manpower Projection'!L43,"") -> 0 | O43: =IFERROR('Manpower Projection'!M43*'Manpower Projection'!H43,"") -> 0
F44: 46073 | K44: =IFERROR('Manpower Projection'!H44*'Manpower Projection'!I44*'Manpower Projection'!J44,0) -> 0 | L44: {='Manpower Projection'!$L$16} -> 51.69 | M44: ='Manpower Projection'!$M$16 -> 83.54931 | N44: =IFERROR('Manpower Projection'!H44*'Manpower Projection'!L44,"") -> 0 | O44: =IFERROR('Manpower Projection'!M44*'Manpower Projection'!H44,"") -> 0
F45: 46080 | K45: =IFERROR('Manpower Projection'!H45*'Manpower Projection'!I45*'Manpower Projection'!J45,0) -> 0 | L45: {='Manpower Projection'!$L$16} -> 51.69 | M45: ='Manpower Projection'!$M$16 -> 83.54931 | N45: =IFERROR('Manpower Projection'!H45*'Manpower Projection'!L45,"") -> 0 | O45: =IFERROR('Manpower Projection'!M45*'Manpower Projection'!H45,"") -> 0
F46: 46087 | K46: =IFERROR('Manpower Projection'!H46*'Manpower Projection'!I46*'Manpower Projection'!J46,0) -> 0 | L46: {='Manpower Projection'!$L$16} -> 51.69 | M46: ='Manpower Projection'!$M$16 -> 83.54931 | N46: =IFERROR('Manpower Projection'!H46*'Manpower Projection'!L46,"") -> 0 | O46: =IFERROR('Manpower Projection'!M46*'Manpower Projection'!H46,"") -> 0
F47: 46094 | K47: =IFERROR('Manpower Projection'!H47*'Manpower Projection'!I47*'Manpower Projection'!J47,0) -> 0 | L47: {='Manpower Projection'!$L$16} -> 51.69 | M47: ='Manpower Projection'!$M$16 -> 83.54931 | N47: =IFERROR('Manpower Projection'!H47*'Manpower Projection'!L47,"") -> 0 | O47: =IFERROR('Manpower Projection'!M47*'Manpower Projection'!H47,"") -> 0
F48: 46101 | K48: =IFERROR('Manpower Projection'!H48*'Manpower Projection'!I48*'Manpower Projection'!J48,0) -> 0 | L48: {='Manpower Projection'!$L$16} -> 51.69 | M48: ='Manpower Projection'!$M$16 -> 83.54931 | N48: =IFERROR('Manpower Projection'!H48*'Manpower Projection'!L48,"") -> 0 | O48: =IFERROR('Manpower Projection'!M48*'Manpower Projection'!H48,"") -> 0
F49: 46108 | K49: =IFERROR('Manpower Projection'!H49*'Manpower Projection'!I49*'Manpower Projection'!J49,0) -> 0 | L49: {='Manpower Projection'!$L$16} -> 51.69 | M49: ='Manpower Projection'!$M$16 -> 83.54931 | N49: =IFERROR('Manpower Projection'!H49*'Manpower Projection'!L49,"") -> 0 | O49: =IFERROR('Manpower Projection'!M49*'Manpower Projection'!H49,"") -> 0
F50: 46115 | K50: =IFERROR('Manpower Projection'!H50*'Manpower Projection'!I50*'Manpower Projection'!J50,0) -> 0 | L50: {='Manpower Projection'!$L$16} -> 51.69 | M50: ='Manpower Projection'!$M$16 -> 83.54931 | N50: =IFERROR('Manpower Projection'!H50*'Manpower Projection'!L50,"") -> 0 | O50: =IFERROR('Manpower Projection'!M50*'Manpower Projection'!H50,"") -> 0
F51: 46122 | K51: =IFERROR('Manpower Projection'!H51*'Manpower Projection'!I51*'Manpower Projection'!J51,0) -> 0 | L51: {='Manpower Projection'!$L$16} -> 51.69 | M51: ='Manpower Projection'!$M$16 -> 83.54931 | N51: =IFERROR('Manpower Projection'!H51*'Manpower Projection'!L51,"") -> 0 | O51: =IFERROR('Manpower Projection'!M51*'Manpower Projection'!H51,"") -> 0
...

Sheet Labor Projection
B1: JOINT RESERVE BASE HANGAR | H1: ='Manpower Projection'!M25 -> -12624.476 | I1: Projected Composite Rate: | K1: {='Manpower Projection'!I13} -> #DIV/0! | L1: Projected Burden Rate: | N1: ='Manpower Projection'!I14-'Manpower Projection'!I13 -> #DIV/0!
B2: Job to Date Labor
A3: Final | B3: 12 | C3: 2025 | D3: 2025-12-31
D10: =SUM(LaborProj[Original Hours Estimate])+SUM(NTPLH[Original Hours Estimate]) -> 12878 | E10: =SUM(LaborProj[Change Order Hours Estimate])+SUM(NTPLH[Change Order Hours Estimate]) -> 0 | F10: =SUM(LaborProj[Current Labor Hours Estimate])+SUM(NTPLH[Current Labor Hours Estimate]) -> #REF! | G10: =SUM(LaborProj[JTD Hours])+SUM(NTPLH[JTD Hours]) -> 290 | H10: =IFERROR(G10/M10,0) -> 0.022455422 | I10: =SUM(LaborProj[Base Hrs to Complete])+SUM(NTPLH[Base Hrs to Complete]) -> 12624.476 | K10: =SUM(LaborProj[Productivity Hours])+SUM(NTPLH[Productivity Hours]) -> 0 | L10: =SUM(LaborProj[Projected Hrs to Complete])+SUM(NTPLH[Projected Hrs to Complete]) -> 12624.476 | M10: =SUM(LaborProj[Total Hrs])+SUM(NTPLH[Total Hrs]) -> 12914.476 | N10: =SUM(LaborProj[(Under) / Over ])+SUM(NTPLH[(Under) / Over]) -> 36.475796 | O10: =SUM(LaborProj[ Original Labor Dollar Est. ])+SUM(NTPLH[Original Labor Dollar Est.]) -> 508684 | P10: =SUM(LaborProj[ Change Order Labor Dollar Est. ])+SUM(NTPLH[Change Order Labor Dollar Est.]) -> 0 | Q10: =SUM(LaborProj[[ Current Labor Dollar Estimate ]])+SUM(NTPLH[[ Current Labor Dollar Estimate ]]) -> #REF! | R10: =SUM(LaborProj[[ JTD Labor Cost ]])+SUM(NTPLH[[ JTD Labor Cost ]]) -> 14989.17 | S10: =SUM(LaborProj[[ Est Labor to Complete]])+SUM(NTPLH[[ Est Labor to Complete]]) -> 0 | T10: =SUM(LaborProj[ Est. Total Labor ])+SUM(NTPLH[ Est. Total Labor ]) -> 0 | U10: =SUM(LaborProj[(Under) / Over ])+SUM(NTPLH[(Under)/Over]) -> 0 | V10: =SUM(LaborProj[ Est. $/Hour ])+SUM(NTPLH[Est. $/Hour]) -> 790.00852 | W10: =SUM(LaborProj[ JTD $/ Hr ])+SUM(NTPLH[JTD $/ Hr]) -> 211.51135 | X10: =SUM(LaborProj[(Under) / Over ])+SUM(NTPLH[(Under) / Over2]) -> -578.49716
B11: Phase | C11: Cost Type | D11: Original Hours Estimate | E11: Change Order Hours Estimate | F11: Current Labor Hours Estimate | G11: JTD Hours | H11: Est. % Complete | I11: Base Hrs to Complete | J11: Productivity Factor | K11: Productivity Hours | L11: Projected Hrs to Complete | M11: Total Hrs | N11: (Under) / Over | O11: Original Labor Dollar Est. | P11: Change Order Labor Dollar Est. | Q11: Current Labor Dollar Estimate | R11: JTD Labor Cost | S11: Est Labor to Complete | T11: Est. Total Labor | U11: (Under) / Over | V11: Est. $/Hour | W11: JTD $/ Hr | X11: (Under) / Over | Y11: CostType | Z11: PhaseCenter
B12: 00300321 - PROJECT ENGINEER | C12: L | D12: 0 | E12: =IFERROR('Labor Projection'!F12-'Labor Projection'!D12,"") -> 0 | F12: 0 | G12: 16 | I12: =IFERROR(IF('Labor Projection'!H12=0,'Labor Projection'!F12,(('Labor Projection'!G12/'Labor Projection'!H12)-'Labor Projection'!G12)),"") -> 0 | K12: =IFERROR('Labor Projection'!I12*'Labor Projection'!J12,"") -> 0 | L12: =IFERROR('Labor Projection'!I12+'Labor Projection'!K12,"") -> 0 | M12: =IFERROR('Labor Projection'!L12+'Labor Projection'!G12,"") -> 16 | N12: =IFERROR('Labor Projection'!M12-'Labor Projection'!F12,"") -> 16 | O12: 0 | P12: =IFERROR('Labor Projection'!Q12-'Labor Projection'!O12,"") -> 0 | Q12: 0 | R12: 901.6 | S12: =IFERROR('Labor Projection'!L12*'Labor Projection'!$K$1,"") | T12: =IFERROR('Labor Projection'!R12+'Labor Projection'!S12,"") | U12: =IFERROR('Labor Projection'!T12-'Labor Projection'!Q12,"") | V12: =IFERROR(IF('Labor Projection'!D12=0,0,'Labor Projection'!O12/'Labor Projection'!D12),"") -> 0 | W12: =IFERROR(IF('Labor Projection'!G12=0,0,'Labor Projection'!R12/'Labor Projection'!G12),"") -> 56.35 | X12: =IFERROR('Labor Projection'!W12-'Labor Projection'!V12,"") -> 56.35 | Y12: L | Z12: 0050301000
B13: 00300321 - PROJECT ENGINEER | C13: LA | D13: 0 | E13: =IFERROR('Labor Projection'!F13-'Labor Projection'!D13,"") -> 0 | F13: 0 | I13: =IFERROR(IF('Labor Projection'!H13=0,'Labor Projection'!F13,(('Labor Projection'!G13/'Labor Projection'!H13)-'Labor Projection'!G13)),"") -> 0 | K13: =IFERROR('Labor Projection'!I13*'Labor Projection'!J13,"") -> 0 | L13: =IFERROR('Labor Projection'!I13+'Labor Projection'!K13,"") -> 0 | M13: =IFERROR('Labor Projection'!L13+'Labor Projection'!G13,"") -> 0 | N13: =IFERROR('Labor Projection'!M13-'Labor Projection'!F13,"") -> 0 | O13: 0 | P13: =IFERROR('Labor Projection'!Q13-'Labor Projection'!O13,"") -> 0 | Q13: 0 | S13: =IFERROR('Labor Projection'!L13*'Labor Projection'!$K$1,"") | T13: =IFERROR('Labor Projection'!R13+'Labor Projection'!S13,"") | U13: =IFERROR('Labor Projection'!T13-'Labor Projection'!Q13,"") | V13: =IFERROR(IF('Labor Projection'!D13=0,0,'Labor Projection'!O13/'Labor Projection'!D13),"") -> 0 | W13: =IFERROR(IF('Labor Projection'!G13=0,0,'Labor Projection'!R13/'Labor Projection'!G13),"") -> 0 | X13: =IFERROR('Labor Projection'!W13-'Labor Projection'!V13,"") -> 0 | Y13: LA | Z13: 0050301000
B14: 00300321 - PROJECT ENGINEER | C14: LB | D14: 0 | E14: =IFERROR('Labor Projection'!F14-'Labor Projection'!D14,"") -> 0 | F14: 0 | I14: =IFERROR(IF('Labor Projection'!H14=0,'Labor Projection'!F14,(('Labor Projection'!G14/'Labor Projection'!H14)-'Labor Projection'!G14)),"") -> 0 | K14: =IFERROR('Labor Projection'!I14*'Labor Projection'!J14,"") -> 0 | L14: =IFERROR('Labor Projection'!I14+'Labor Projection'!K14,"") -> 0 | M14: =IFERROR('Labor Projection'!L14+'Labor Projection'!G14,"") -> 0 | N14: =IFERROR('Labor Projection'!M14-'Labor Projection'!F14,"") -> 0 | O14: 0 | P14: =IFERROR('Labor Projection'!Q14-'Labor Projection'!O14,"") -> 0 | Q14: 0 | S14: =IFERROR('Labor Projection'!L14*'Labor Projection'!$K$1,"") | T14: =IFERROR('Labor Projection'!R14+'Labor Projection'!S14,"") | U14: =IFERROR('Labor Projection'!T14-'Labor Projection'!Q14,"") | V14: =IFERROR(IF('Labor Projection'!D14=0,0,'Labor Projection'!O14/'Labor Projection'!D14),"") -> 0 | W14: =IFERROR(IF('Labor Projection'!G14=0,0,'Labor Projection'!R14/'Labor Projection'!G14),"") -> 0 | X14: =IFERROR('Labor Projection'!W14-'Labor Projection'!V14,"") -> 0 | Y14: LB | Z14: 0050301000
B15: 00300321 - PROJECT ENGINEER | C15: LD | D15: 0 | E15: =IFERROR('Labor Projection'!F15-'Labor Projection'!D15,"") -> 0 | F15: 0 | I15: =IFERROR(IF('Labor Projection'!H15=0,'Labor Projection'!F15,(('Labor Projection'!G15/'Labor Projection'!H15)-'Labor Projection'!G15)),"") -> 0 | K15: =IFERROR('Labor Projection'!I15*'Labor Projection'!J15,"") -> 0 | L15: =IFERROR('Labor Projection'!I15+'Labor Projection'!K15,"") -> 0 | M15: =IFERROR('Labor Projection'!L15+'Labor Projection'!G15,"") -> 0 | N15: =IFERROR('Labor Projection'!M15-'Labor Projection'!F15,"") -> 0 | O15: 0 | P15: =IFERROR('Labor Projection'!Q15-'Labor Projection'!O15,"") -> 0 | Q15: 0 | S15: =IFERROR('Labor Projection'!L15*'Labor Projection'!$K$1,"") | T15: =IFERROR('Labor Projection'!R15+'Labor Projection'!S15,"") | U15: =IFERROR('Labor Projection'!T15-'Labor Projection'!Q15,"") | V15: =IFERROR(IF('Labor Projection'!D15=0,0,'Labor Projection'!O15/'Labor Projection'!D15),"") -> 0 | W15: =IFERROR(IF('Labor Projection'!G15=0,0,'Labor Projection'!R15/'Labor Projection'!G15),"") -> 0 | X15: =IFERROR('Labor Projection'!W15-'Labor Projection'!V15,"") -> 0 | Y15: LD | Z15: 0050301000
B16: 00300321 - PROJECT ENGINEER | C16: LM | D16: 0 | E16: =IFERROR('Labor Projection'!F16-'Labor Projection'!D16,"") -> 0 | F16: 0 | I16: =IFERROR(IF('Labor Projection'!H16=0,'Labor Projection'!F16,(('Labor Projection'!G16/'Labor Projection'!H16)-'Labor Projection'!G16)),"") -> 0 | K16: =IFERROR('Labor Projection'!I16*'Labor Projection'!J16,"") -> 0 | L16: =IFERROR('Labor Projection'!I16+'Labor Projection'!K16,"") -> 0 | M16: =IFERROR('Labor Projection'!L16+'Labor Projection'!G16,"") -> 0 | N16: =IFERROR('Labor Projection'!M16-'Labor Projection'!F16,"") -> 0 | O16: 0 | P16: =IFERROR('Labor Projection'!Q16-'Labor Projection'!O16,"") -> 0 | Q16: 0 | S16: =IFERROR('Labor Projection'!L16*'Labor Projection'!$K$1,"") | T16: =IFERROR('Labor Projection'!R16+'Labor Projection'!S16,"") | U16: =IFERROR('Labor Projection'!T16-'Labor Projection'!Q16,"") | V16: =IFERROR(IF('Labor Projection'!D16=0,0,'Labor Projection'!O16/'Labor Projection'!D16),"") -> 0 | W16: =IFERROR(IF('Labor Projection'!G16=0,0,'Labor Projection'!R16/'Labor Projection'!G16),"") -> 0 | X16: =IFERROR('Labor Projection'!W16-'Labor Projection'!V16,"") -> 0 | Y16: LM | Z16: 0050301000
B17: 00400000 - ALL LABOR | C17: L | D17: 0 | E17: =IFERROR('Labor Projection'!F17-'Labor Projection'!D17,"") -> 0 | F17: 0 | I17: =IFERROR(IF('Labor Projection'!H17=0,'Labor Projection'!F17,(('Labor Projection'!G17/'Labor Projection'!H17)-'Labor Projection'!G17)),"") -> 0 | K17: =IFERROR('Labor Projection'!I17*'Labor Projection'!J17,"") -> 0 | L17: =IFERROR('Labor Projection'!I17+'Labor Projection'!K17,"") -> 0 | M17: =IFERROR('Labor Projection'!L17+'Labor Projection'!G17,"") -> 0 | N17: =IFERROR('Labor Projection'!M17-'Labor Projection'!F17,"") -> 0 | O17: 0 | P17: =IFERROR('Labor Projection'!Q17-'Labor Projection'!O17,"") -> 0 | Q17: 0 | S17: =IFERROR('Labor Projection'!L17*'Labor Projection'!$K$1,"") | T17: =IFERROR('Labor Projection'!R17+'Labor Projection'!S17,"") | U17: =IFERROR('Labor Projection'!T17-'Labor Projection'!Q17,"") | V17: =IFERROR(IF('Labor Projection'!D17=0,0,'Labor Projection'!O17/'Labor Projection'!D17),"") -> 0 | W17: =IFERROR(IF('Labor Projection'!G17=0,0,'Labor Projection'!R17/'Labor Projection'!G17),"") -> 0 | X17: =IFERROR('Labor Projection'!W17-'Labor Projection'!V17,"") -> 0 | Y17: L | Z17: 0050301000
B18: 00400000 - ALL LABOR | C18: LA | D18: 0 | E18: =IFERROR('Labor Projection'!F18-'Labor Projection'!D18,"") -> 0 | F18: 0 | I18: =IFERROR(IF('Labor Projection'!H18=0,'Labor Projection'!F18,(('Labor Projection'!G18/'Labor Projection'!H18)-'Labor Projection'!G18)),"") -> 0 | K18: =IFERROR('Labor Projection'!I18*'Labor Projection'!J18,"") -> 0 | L18: =IFERROR('Labor Projection'!I18+'Labor Projection'!K18,"") -> 0 | M18: =IFERROR('Labor Projection'!L18+'Labor Projection'!G18,"") -> 0 | N18: =IFERROR('Labor Projection'!M18-'Labor Projection'!F18,"") -> 0 | O18: 0 | P18: =IFERROR('Labor Projection'!Q18-'Labor Projection'!O18,"") -> 0 | Q18: 0 | S18: =IFERROR('Labor Projection'!L18*'Labor Projection'!$K$1,"") | T18: =IFERROR('Labor Projection'!R18+'Labor Projection'!S18,"") | U18: =IFERROR('Labor Projection'!T18-'Labor Projection'!Q18,"") | V18: =IFERROR(IF('Labor Projection'!D18=0,0,'Labor Projection'!O18/'Labor Projection'!D18),"") -> 0 | W18: =IFERROR(IF('Labor Projection'!G18=0,0,'Labor Projection'!R18/'Labor Projection'!G18),"") -> 0 | X18: =IFERROR('Labor Projection'!W18-'Labor Projection'!V18,"") -> 0 | Y18: LA | Z18: 0050301000
B19: 00400000 - ALL LABOR | C19: LB | D19: 0 | E19: =IFERROR('Labor Projection'!F19-'Labor Projection'!D19,"") -> 0 | F19: 0 | I19: =IFERROR(IF('Labor Projection'!H19=0,'Labor Projection'!F19,(('Labor Projection'!G19/'Labor Projection'!H19)-'Labor Projection'!G19)),"") -> 0 | K19: =IFERROR('Labor Projection'!I19*'Labor Projection'!J19,"") -> 0 | L19: =IFERROR('Labor Projection'!I19+'Labor Projection'!K19,"") -> 0 | M19: =IFERROR('Labor Projection'!L19+'Labor Projection'!G19,"") -> 0 | N19: =IFERROR('Labor Projection'!M19-'Labor Projection'!F19,"") -> 0 | O19: 0 | P19: =IFERROR('Labor Projection'!Q19-'Labor Projection'!O19,"") -> 0 | Q19: 0 | S19: =IFERROR('Labor Projection'!L19*'Labor Projection'!$K$1,"") | T19: =IFERROR('Labor Projection'!R19+'Labor Projection'!S19,"") | U19: =IFERROR('Labor Projection'!T19-'Labor Projection'!Q19,"") | V19: =IFERROR(IF('Labor Projection'!D19=0,0,'Labor Projection'!O19/'Labor Projection'!D19),"") -> 0 | W19: =IFERROR(IF('Labor Projection'!G19=0,0,'Labor Projection'!R19/'Labor Projection'!G19),"") -> 0 | X19: =IFERROR('Labor Projection'!W19-'Labor Projection'!V19,"") -> 0 | Y19: LB | Z19: 0050301000
B20: 00400000 - ALL LABOR | C20: LD | D20: 0 | E20: =IFERROR('Labor Projection'!F20-'Labor Projection'!D20,"") -> 0 | F20: 0 | I20: =IFERROR(IF('Labor Projection'!H20=0,'Labor Projection'!F20,(('Labor Projection'!G20/'Labor Projection'!H20)-'Labor Projection'!G20)),"") -> 0 | K20: =IFERROR('Labor Projection'!I20*'Labor Projection'!J20,"") -> 0 | L20: =IFERROR('Labor Projection'!I20+'Labor Projection'!K20,"") -> 0 | M20: =IFERROR('Labor Projection'!L20+'Labor Projection'!G20,"") -> 0 | N20: =IFERROR('Labor Projection'!M20-'Labor Projection'!F20,"") -> 0 | O20: 0 | P20: =IFERROR('Labor Projection'!Q20-'Labor Projection'!O20,"") -> 0 | Q20: 0 | S20: =IFERROR('Labor Projection'!L20*'Labor Projection'!$K$1,"") | T20: =IFERROR('Labor Projection'!R20+'Labor Projection'!S20,"") | U20: =IFERROR('Labor Projection'!T20-'Labor Projection'!Q20,"") | V20: =IFERROR(IF('Labor Projection'!D20=0,0,'Labor Projection'!O20/'Labor Projection'!D20),"") -> 0 | W20: =IFERROR(IF('Labor Projection'!G20=0,0,'Labor Projection'!R20/'Labor Projection'!G20),"") -> 0 | X20: =IFERROR('Labor Projection'!W20-'Labor Projection'!V20,"") -> 0 | Y20: LD | Z20: 0050301000
B21: 00400000 - ALL LABOR | C21: LM | D21: 0 | E21: =IFERROR('Labor Projection'!F21-'Labor Projection'!D21,"") -> 0 | F21: 0 | I21: =IFERROR(IF('Labor Projection'!H21=0,'Labor Projection'!F21,(('Labor Projection'!G21/'Labor Projection'!H21)-'Labor Projection'!G21)),"") -> 0 | K21: =IFERROR('Labor Projection'!I21*'Labor Projection'!J21,"") -> 0 | L21: =IFERROR('Labor Projection'!I21+'Labor Projection'!K21,"") -> 0 | M21: =IFERROR('Labor Projection'!L21+'Labor Projection'!G21,"") -> 0 | N21: =IFERROR('Labor Projection'!M21-'Labor Projection'!F21,"") -> 0 | O21: 0 | P21: =IFERROR('Labor Projection'!Q21-'Labor Projection'!O21,"") -> 0 | Q21: 0 | S21: =IFERROR('Labor Projection'!L21*'Labor Projection'!$K$1,"") | T21: =IFERROR('Labor Projection'!R21+'Labor Projection'!S21,"") | U21: =IFERROR('Labor Projection'!T21-'Labor Projection'!Q21,"") | V21: =IFERROR(IF('Labor Projection'!D21=0,0,'Labor Projection'!O21/'Labor Projection'!D21),"") -> 0 | W21: =IFERROR(IF('Labor Projection'!G21=0,0,'Labor Projection'!R21/'Labor Projection'!G21),"") -> 0 | X21: =IFERROR('Labor Projection'!W21-'Labor Projection'!V21,"") -> 0 | Y21: LM | Z21: 0050301000
B22: 00400401 - LIGHT FIXTURES | C22: L | D22: 752 | E22: =IFERROR('Labor Projection'!F22-'Labor Projection'!D22,"") -> 0 | F22: 752 | I22: =IFERROR(IF('Labor Projection'!H22=0,'Labor Projection'!F22,(('Labor Projection'!G22/'Labor Projection'!H22)-'Labor Projection'!G22)),"") -> 752 | K22: =IFERROR('Labor Projection'!I22*'Labor Projection'!J22,"") -> 0 | L22: =IFERROR('Labor Projection'!I22+'Labor Projection'!K22,"") -> 752 | M22: =IFERROR('Labor Projection'!L22+'Labor Projection'!G22,"") -> 752 | N22: =IFERROR('Labor Projection'!M22-'Labor Projection'!F22,"") -> 0 | O22: 29704 | P22: =IFERROR('Labor Projection'!Q22-'Labor Projection'!O22,"") -> 0 | Q22: 29704 | S22: =IFERROR('Labor Projection'!L22*'Labor Projection'!$K$1,"") | T22: =IFERROR('Labor Projection'!R22+'Labor Projection'!S22,"") | U22: =IFERROR('Labor Projection'!T22-'Labor Projection'!Q22,"") | V22: =IFERROR(IF('Labor Projection'!D22=0,0,'Labor Projection'!O22/'Labor Projection'!D22),"") -> 39.5 | W22: =IFERROR(IF('Labor Projection'!G22=0,0,'Labor Projection'!R22/'Labor Projection'!G22),"") -> 0 | X22: =IFERROR('Labor Projection'!W22-'Labor Projection'!V22,"") -> -39.5 | Y22: L | Z22: 0050301000
B23: 00400403 - BW- LIGHTING- ABOVE CEILI | C23: L | D23: 2600 | E23: =IFERROR('Labor Projection'!F23-'Labor Projection'!D23,"") -> 0 | F23: 2600 | I23: =IFERROR(IF('Labor Projection'!H23=0,'Labor Projection'!F23,(('Labor Projection'!G23/'Labor Projection'!H23)-'Labor Projection'!G23)),"") -> 2600 | K23: =IFERROR('Labor Projection'!I23*'Labor Projection'!J23,"") -> 0 | L23: =IFERROR('Labor Projection'!I23+'Labor Projection'!K23,"") -> 2600 | M23: =IFERROR('Labor Projection'!L23+'Labor Projection'!G23,"") -> 2600 | N23: =IFERROR('Labor Projection'!M23-'Labor Projection'!F23,"") -> 0 | O23: 102700 | P23: =IFERROR('Labor Projection'!Q23-'Labor Projection'!O23,"") -> 0 | Q23: 102700 | S23: =IFERROR('Labor Projection'!L23*'Labor Projection'!$K$1,"") | T23: =IFERROR('Labor Projection'!R23+'Labor Projection'!S23,"") | U23: =IFERROR('Labor Projection'!T23-'Labor Projection'!Q23,"") | V23: =IFERROR(IF('Labor Projection'!D23=0,0,'Labor Projection'!O23/'Labor Projection'!D23),"") -> 39.5 | W23: =IFERROR(IF('Labor Projection'!G23=0,0,'Labor Projection'!R23/'Labor Projection'!G23),"") -> 0 | X23: =IFERROR('Labor Projection'!W23-'Labor Projection'!V23,"") -> -39.5 | Y23: L | Z23: 0050301000
B24: 00400404 - WIRING DEVICES- LIGHTING | C24: L | D24: 229 | E24: =IFERROR('Labor Projection'!F24-'Labor Projection'!D24,"") -> 0 | F24: 229 | I24: =IFERROR(IF('Labor Projection'!H24=0,'Labor Projection'!F24,(('Labor Projection'!G24/'Labor Projection'!H24)-'Labor Projection'!G24)),"") -> 229 | K24: =IFERROR('Labor Projection'!I24*'Labor Projection'!J24,"") -> 0 | L24: =IFERROR('Labor Projection'!I24+'Labor Projection'!K24,"") -> 229 | M24: =IFERROR('Labor Projection'!L24+'Labor Projection'!G24,"") -> 229 | N24: =IFERROR('Labor Projection'!M24-'Labor Projection'!F24,"") -> 0 | O24: 9046 | P24: =IFERROR('Labor Projection'!Q24-'Labor Projection'!O24,"") -> 0 | Q24: 9046 | S24: =IFERROR('Labor Projection'!L24*'Labor Projection'!$K$1,"") | T24: =IFERROR('Labor Projection'!R24+'Labor Projection'!S24,"") | U24: =IFERROR('Labor Projection'!T24-'Labor Projection'!Q24,"") | V24: =IFERROR(IF('Labor Projection'!D24=0,0,'Labor Projection'!O24/'Labor Projection'!D24),"") -> 39.502183 | W24: =IFERROR(IF('Labor Projection'!G24=0,0,'Labor Projection'!R24/'Labor Projection'!G24),"") -> 0 | X24: =IFERROR('Labor Projection'!W24-'Labor Projection'!V24,"") -> -39.502183 | Y24: L | Z24: 0050301000
... B26: 00400408 - GEAR | C26: L | D26: 331 | E26: =IFERROR('Labor Projection'!F26-'Labor Projection'!D26,"") -> 0 | F26: 331 | I26: =IFERROR(IF('Labor Projection'!H26=0,'Labor Projection'!F26,(('Labor Projection'!G26/'Labor Projection'!H26)-'Labor Projection'!G26)),"") -> 331 | K26: =IFERROR('Labor Projection'!I26*'Labor Projection'!J26,"") -> 0 | L26: =IFERROR('Labor Projection'!I26+'Labor Projection'!K26,"") -> 331 | M26: =IFERROR('Labor Projection'!L26+'Labor Projection'!G26,"") -> 331 | N26: =IFERROR('Labor Projection'!M26-'Labor Projection'!F26,"") -> 0 | O26: 13075 | P26: =IFERROR('Labor Projection'!Q26-'Labor Projection'!O26,"") -> 0 | Q26: 13075 | S26: =IFERROR('Labor Projection'!L26*'Labor Projection'!$K$1,"") | T26: =IFERROR('Labor Projection'!R26+'Labor Projection'!S26,"") | U26: =IFERROR('Labor Projection'!T26-'Labor Projection'!Q26,"") | V26: =IFERROR(IF('Labor Projection'!D26=0,0,'Labor Projection'!O26/'Labor Projection'!D26),"") -> 39.501511 | W26: =IFERROR(IF('Labor Projection'!G26=0,0,'Labor Projection'!R26/'Labor Projection'!G26),"") -> 0 | X26: =IFERROR('Labor Projection'!W26-'Labor Projection'!V26,"") -> -39.501511 | Y26: L | Z26: 0050301000
B27: 00400409 - TEMPORARY | C27: L | D27: 360 | E27: =IFERROR('Labor Projection'!F27-'Labor Projection'!D27,"") -> 0 | F27: 360 | G27: 131 | H27: 0.36 | I27: =IFERROR(IF('Labor Projection'!H27=0,'Labor Projection'!F27,(('Labor Projection'!G27/'Labor Projection'!H27)-'Labor Projection'!G27)),"") -> 232.88889 | K27: =IFERROR('Labor Projection'!I27*'Labor Projection'!J27,"") -> 0 | L27: =IFERROR('Labor Projection'!I27+'Labor Projection'!K27,"") -> 232.88889 | M27: =IFERROR('Labor Projection'!L27+'Labor Projection'!G27,"") -> 363.88889 | N27: =IFERROR('Labor Projection'!M27-'Labor Projection'!F27,"") -> 3.8888889 | O27: 14220 | P27: =IFERROR('Labor Projection'!Q27-'Labor Projection'!O27,"") -> 0 | Q27: 14220 | R27: 6609.13 | S27: =IFERROR('Labor Projection'!L27*'Labor Projection'!$K$1,"") | T27: =IFERROR('Labor Projection'!R27+'Labor Projection'!S27,"") | U27: =IFERROR('Labor Projection'!T27-'Labor Projection'!Q27,"") | V27: =IFERROR(IF('Labor Projection'!D27=0,0,'Labor Projection'!O27/'Labor Projection'!D27),"") -> 39.5 | W27: =IFERROR(IF('Labor Projection'!G27=0,0,'Labor Projection'!R27/'Labor Projection'!G27),"") -> 50.451374 | X27: =IFERROR('Labor Projection'!W27-'Labor Projection'!V27,"") -> 10.951374 | Y27: L | Z27: 0050301000
B28: 00400413 - FIRE ALARM | C28: L | D28: 496 | E28: =IFERROR('Labor Projection'!F28-'Labor Projection'!D28,"") -> 0 | F28: 496 | I28: =IFERROR(IF('Labor Projection'!H28=0,'Labor Projection'!F28,(('Labor Projection'!G28/'Labor Projection'!H28)-'Labor Projection'!G28)),"") -> 496 | K28: =IFERROR('Labor Projection'!I28*'Labor Projection'!J28,"") -> 0 | L28: =IFERROR('Labor Projection'!I28+'Labor Projection'!K28,"") -> 496 | M28: =IFERROR('Labor Projection'!L28+'Labor Projection'!G28,"") -> 496 | N28: =IFERROR('Labor Projection'!M28-'Labor Projection'!F28,"") -> 0 | O28: 19592 | P28: =IFERROR('Labor Projection'!Q28-'Labor Projection'!O28,"") -> 0 | Q28: 19592 | S28: =IFERROR('Labor Projection'!L28*'Labor Projection'!$K$1,"") | T28: =IFERROR('Labor Projection'!R28+'Labor Projection'!S28,"") | U28: =IFERROR('Labor Projection'!T28-'Labor Projection'!Q28,"") | V28: =IFERROR(IF('Labor Projection'!D28=0,0,'Labor Projection'!O28/'Labor Projection'!D28),"") -> 39.5 | W28: =IFERROR(IF('Labor Projection'!G28=0,0,'Labor Projection'!R28/'Labor Projection'!G28),"") -> 0 | X28: =IFERROR('Labor Projection'!W28-'Labor Projection'!V28,"") -> -39.5 | Y28: L | Z28: 0050301000
B29: 00400416 - DEMO | C29: L | D29: 180 | E29: =IFERROR('Labor Projection'!F29-'Labor Projection'!D29,"") -> 0 | F29: 180 | G29: 80 | H29: 0.443 | I29: =IFERROR(IF('Labor Projection'!H29=0,'Labor Projection'!F29,(('Labor Projection'!G29/'Labor Projection'!H29)-'Labor Projection'!G29)),"") -> 100.58691 | K29: =IFERROR('Labor Projection'!I29*'Labor Projection'!J29,"") -> 0 | L29: =IFERROR('Labor Projection'!I29+'Labor Projection'!K29,"") -> 100.58691 | M29: =IFERROR('Labor Projection'!L29+'Labor Projection'!G29,"") -> 180.58691 | N29: =IFERROR('Labor Projection'!M29-'Labor Projection'!F29,"") -> 0.58690745 | O29: 7110 | P29: =IFERROR('Labor Projection'!Q29-'Labor Projection'!O29,"") -> 0 | Q29: 7110 | R29: 4149.23 | S29: =IFERROR('Labor Projection'!L29*'Labor Projection'!$K$1,"") | T29: =IFERROR('Labor Projection'!R29+'Labor Projection'!S29,"") | U29: =IFERROR('Labor Projection'!T29-'Labor Projection'!Q29,"") | V29: =IFERROR(IF('Labor Projection'!D29=0,0,'Labor Projection'!O29/'Labor Projection'!D29),"") -> 39.5 | W29: =IFERROR(IF('Labor Projection'!G29=0,0,'Labor Projection'!R29/'Labor Projection'!G29),"") -> 51.865375 | X29: =IFERROR('Labor Projection'!W29-'Labor Projection'!V29,"") -> 12.365375 | Y29: L | Z29: 0050301000
B30: 00400417 - GROUNDING | C30: L | D30: 269 | E30: =IFERROR('Labor Projection'!F30-'Labor Projection'!D30,"") -> 0 | F30: 269 | I30: =IFERROR(IF('Labor Projection'!H30=0,'Labor Projection'!F30,(('Labor Projection'!G30/'Labor Projection'!H30)-'Labor Projection'!G30)),"") -> 269 | K30: =IFERROR('Labor Projection'!I30*'Labor Projection'!J30,"") -> 0 | L30: =IFERROR('Labor Projection'!I30+'Labor Projection'!K30,"") -> 269 | M30: =IFERROR('Labor Projection'!L30+'Labor Projection'!G30,"") -> 269 | N30: =IFERROR('Labor Projection'!M30-'Labor Projection'!F30,"") -> 0 | O30: 10626 | P30: =IFERROR('Labor Projection'!Q30-'Labor Projection'!O30,"") -> 0 | Q30: 10626 | S30: =IFERROR('Labor Projection'!L30*'Labor Projection'!$K$1,"") | T30: =IFERROR('Labor Projection'!R30+'Labor Projection'!S30,"") | U30: =IFERROR('Labor Projection'!T30-'Labor Projection'!Q30,"") | V30: =IFERROR(IF('Labor Projection'!D30=0,0,'Labor Projection'!O30/'Labor Projection'!D30),"") -> 39.501859 | W30: =IFERROR(IF('Labor Projection'!G30=0,0,'Labor Projection'!R30/'Labor Projection'!G30),"") -> 0 | X30: =IFERROR('Labor Projection'!W30-'Labor Projection'!V30,"") -> -39.501859 | Y30: L | Z30: 0050301000
B31: 00400418 - TECHNOLOGIES | C31: L | D31: 358 | E31: =IFERROR('Labor Projection'!F31-'Labor Projection'!D31,"") -> 0 | F31: 358 | I31: =IFERROR(IF('Labor Projection'!H31=0,'Labor Projection'!F31,(('Labor Projection'!G31/'Labor Projection'!H31)-'Labor Projection'!G31)),"") -> 358 | K31: =IFERROR('Labor Projection'!I31*'Labor Projection'!J31,"") -> 0 | L31: =IFERROR('Labor Projection'!I31+'Labor Projection'!K31,"") -> 358 | M31: =IFERROR('Labor Projection'!L31+'Labor Projection'!G31,"") -> 358 | N31: =IFERROR('Labor Projection'!M31-'Labor Projection'!F31,"") -> 0 | O31: 14141 | P31: =IFERROR('Labor Projection'!Q31-'Labor Projection'!O31,"") -> 0 | Q31: 14141 | S31: =IFERROR('Labor Projection'!L31*'Labor Projection'!$K$1,"") | T31: =IFERROR('Labor Projection'!R31+'Labor Projection'!S31,"") | U31: =IFERROR('Labor Projection'!T31-'Labor Projection'!Q31,"") | V31: =IFERROR(IF('Labor Projection'!D31=0,0,'Labor Projection'!O31/'Labor Projection'!D31),"") -> 39.5 | W31: =IFERROR(IF('Labor Projection'!G31=0,0,'Labor Projection'!R31/'Labor Projection'!G31),"") -> 0 | X31: =IFERROR('Labor Projection'!W31-'Labor Projection'!V31,"") -> -39.5 | Y31: L | Z31: 0050301000
B32: 00400419 - SUPERVISION | C32: L | D32: 1484 | E32: =IFERROR('Labor Projection'!F32-'Labor Projection'!D32,"") -> 0 | F32: 1484 | G32: 63 | H32: 0.042 | I32: =IFERROR(IF('Labor Projection'!H32=0,'Labor Projection'!F32,(('Labor Projection'!G32/'Labor Projection'!H32)-'Labor Projection'!G32)),"") -> 1437 | K32: =IFERROR('Labor Projection'!I32*'Labor Projection'!J32,"") -> 0 | L32: =IFERROR('Labor Projection'!I32+'Labor Projection'!K32,"") -> 1437 | M32: =IFERROR('Labor Projection'!L32+'Labor Projection'!G32,"") -> 1500 | N32: =IFERROR('Labor Projection'!M32-'Labor Projection'!F32,"") -> 16 | O32: 58618 | P32: =IFERROR('Labor Projection'!Q32-'Labor Projection'!O32,"") -> 0 | Q32: 58618 | R32: 3329.21 | S32: =IFERROR('Labor Projection'!L32*'Labor Projection'!$K$1,"") | T32: =IFERROR('Labor Projection'!R32+'Labor Projection'!S32,"") | U32: =IFERROR('Labor Projection'!T32-'Labor Projection'!Q32,"") | V32: =IFERROR(IF('Labor Projection'!D32=0,0,'Labor Projection'!O32/'Labor Projection'!D32),"") -> 39.5 | W32: =IFERROR(IF('Labor Projection'!G32=0,0,'Labor Projection'!R32/'Labor Projection'!G32),"") -> 52.844603 | X32: =IFERROR('Labor Projection'!W32-'Labor Projection'!V32,"") -> 13.344603 | Y32: L | Z32: 0050301000
B33: 00400420 - GENERATOR | C33: L | D33: 180 | E33: =IFERROR('Labor Projection'!F33-'Labor Projection'!D33,"") -> 0 | F33: 180 | I33: =IFERROR(IF('Labor Projection'!H33=0,'Labor Projection'!F33,(('Labor Projection'!G33/'Labor Projection'!H33)-'Labor Projection'!G33)),"") -> 180 | K33: =IFERROR('Labor Projection'!I33*'Labor Projection'!J33,"") -> 0 | L33: =IFERROR('Labor Projection'!I33+'Labor Projection'!K33,"") -> 180 | M33: =IFERROR('Labor Projection'!L33+'Labor Projection'!G33,"") -> 180 | N33: =IFERROR('Labor Projection'!M33-'Labor Projection'!F33,"") -> 0 | O33: 7110 | P33: =IFERROR('Labor Projection'!Q33-'Labor Projection'!O33,"") -> 0 | Q33: 7110 | S33: =IFERROR('Labor Projection'!L33*'Labor Projection'!$K$1,"") | T33: =IFERROR('Labor Projection'!R33+'Labor Projection'!S33,"") | U33: =IFERROR('Labor Projection'!T33-'Labor Projection'!Q33,"") | V33: =IFERROR(IF('Labor Projection'!D33=0,0,'Labor Projection'!O33/'Labor Projection'!D33),"") -> 39.5 | W33: =IFERROR(IF('Labor Projection'!G33=0,0,'Labor Projection'!R33/'Labor Projection'!G33),"") -> 0 | X33: =IFERROR('Labor Projection'!W33-'Labor Projection'!V33,"") -> -39.5 | Y33: L | Z33: 0050301000
B34: 00400421 - UG DISTIBUTION/DB | C34: L | D34: 400 | E34: =IFERROR('Labor Projection'!F34-'Labor Projection'!D34,"") -> 0 | F34: 400 | I34: =IFERROR(IF('Labor Projection'!H34=0,'Labor Projection'!F34,(('Labor Projection'!G34/'Labor Projection'!H34)-'Labor Projection'!G34)),"") -> 400 | K34: =IFERROR('Labor Projection'!I34*'Labor Projection'!J34,"") -> 0 | L34: =IFERROR('Labor Projection'!I34+'Labor Projection'!K34,"") -> 400 | M34: =IFERROR('Labor Projection'!L34+'Labor Projection'!G34,"") -> 400 | N34: =IFERROR('Labor Projection'!M34-'Labor Projection'!F34,"") -> 0 | O34: 15800 | P34: =IFERROR('Labor Projection'!Q34-'Labor Projection'!O34,"") -> 0 | Q34: 15800 | S34: =IFERROR('Labor Projection'!L34*'Labor Projection'!$K$1,"") | T34: =IFERROR('Labor Projection'!R34+'Labor Projection'!S34,"") | U34: =IFERROR('Labor Projection'!T34-'Labor Projection'!Q34,"") | V34: =IFERROR(IF('Labor Projection'!D34=0,0,'Labor Projection'!O34/'Labor Projection'!D34),"") -> 39.5 | W34: =IFERROR(IF('Labor Projection'!G34=0,0,'Labor Projection'!R34/'Labor Projection'!G34),"") -> 0 | X34: =IFERROR('Labor Projection'!W34-'Labor Projection'!V34,"") -> -39.5 | Y34: L | Z34: 0050301000
B35: 00400422 - MV CABLE | C35: L | D35: 360 | E35: =IFERROR('Labor Projection'!F35-'Labor Projection'!D35,"") -> 0 | F35: 360 | I35: =IFERROR(IF('Labor Projection'!H35=0,'Labor Projection'!F35,(('Labor Projection'!G35/'Labor Projection'!H35)-'Labor Projection'!G35)),"") -> 360 | K35: =IFERROR('Labor Projection'!I35*'Labor Projection'!J35,"") -> 0 | L35: =IFERROR('Labor Projection'!I35+'Labor Projection'!K35,"") -> 360 | M35: =IFERROR('Labor Projection'!L35+'Labor Projection'!G35,"") -> 360 | N35: =IFERROR('Labor Projection'!M35-'Labor Projection'!F35,"") -> 0 | O35: 14220 | P35: =IFERROR('Labor Projection'!Q35-'Labor Projection'!O35,"") -> 0 | Q35: 14220 | S35: =IFERROR('Labor Projection'!L35*'Labor Projection'!$K$1,"") | T35: =IFERROR('Labor Projection'!R35+'Labor Projection'!S35,"") | U35: =IFERROR('Labor Projection'!T35-'Labor Projection'!Q35,"") | V35: =IFERROR(IF('Labor Projection'!D35=0,0,'Labor Projection'!O35/'Labor Projection'!D35),"") -> 39.5 | W35: =IFERROR(IF('Labor Projection'!G35=0,0,'Labor Projection'!R35/'Labor Projection'!G35),"") -> 0 | X35: =IFERROR('Labor Projection'!W35-'Labor Projection'!V35,"") -> -39.5 | Y35: L | Z35: 0050301000
B36: 00400423 - MV TERMINATIONS | C36: L | D36: 88 | E36: =IFERROR('Labor Projection'!F36-'Labor Projection'!D36,"") -> 0 | F36: 88 | I36: =IFERROR(IF('Labor Projection'!H36=0,'Labor Projection'!F36,(('Labor Projection'!G36/'Labor Projection'!H36)-'Labor Projection'!G36)),"") -> 88 | K36: =IFERROR('Labor Projection'!I36*'Labor Projection'!J36,"") -> 0 | L36: =IFERROR('Labor Projection'!I36+'Labor Projection'!K36,"") -> 88 | M36: =IFERROR('Labor Projection'!L36+'Labor Projection'!G36,"") -> 88 | N36: =IFERROR('Labor Projection'!M36-'Labor Projection'!F36,"") -> 0 | O36: 3476 | P36: =IFERROR('Labor Projection'!Q36-'Labor Projection'!O36,"") -> 0 | Q36: 3476 | S36: =IFERROR('Labor Projection'!L36*'Labor Projection'!$K$1,"") | T36: =IFERROR('Labor Projection'!R36+'Labor Projection'!S36,"") | U36: =IFERROR('Labor Projection'!T36-'Labor Projection'!Q36,"") | V36: =IFERROR(IF('Labor Projection'!D36=0,0,'Labor Projection'!O36/'Labor Projection'!D36),"") -> 39.5 | W36: =IFERROR(IF('Labor Projection'!G36=0,0,'Labor Projection'!R36/'Labor Projection'!G36),"") -> 0 | X36: =IFERROR('Labor Projection'!W36-'Labor Projection'!V36,"") -> -39.5 | Y36: L | Z36: 0050301000
B37: 00400424 - START UP & COMMISIONING | C37: L | D37: 80 | E37: =IFERROR('Labor Projection'!F37-'Labor Projection'!D37,"") -> 0 | F37: 80 | I37: =IFERROR(IF('Labor Projection'!H37=0,'Labor Projection'!F37,(('Labor Projection'!G37/'Labor Projection'!H37)-'Labor Projection'!G37)),"") -> 80 | K37: =IFERROR('Labor Projection'!I37*'Labor Projection'!J37,"") -> 0 | L37: =IFERROR('Labor Projection'!I37+'Labor Projection'!K37,"") -> 80 | M37: =IFERROR('Labor Projection'!L37+'Labor Projection'!G37,"") -> 80 | N37: =IFERROR('Labor Projection'!M37-'Labor Projection'!F37,"") -> 0 | O37: 3160 | P37: =IFERROR('Labor Projection'!Q37-'Labor Projection'!O37,"") -> 0 | Q37: 3160 | S37: =IFERROR('Labor Projection'!L37*'Labor Projection'!$K$1,"") | T37: =IFERROR('Labor Projection'!R37+'Labor Projection'!S37,"") | U37: =IFERROR('Labor Projection'!T37-'Labor Projection'!Q37,"") | V37: =IFERROR(IF('Labor Projection'!D37=0,0,'Labor Projection'!O37/'Labor Projection'!D37),"") -> 39.5 | W37: =IFERROR(IF('Labor Projection'!G37=0,0,'Labor Projection'!R37/'Labor Projection'!G37),"") -> 0 | X37: =IFERROR('Labor Projection'!W37-'Labor Projection'!V37,"") -> -39.5 | Y37: L | Z37: 0050301000
B38: 00400425 - PUNCHLIST | C38: L | D38: 120 | E38: =IFERROR('Labor Projection'!F38-'Labor Projection'!D38,"") -> 0 | F38: 120 | I38: =IFERROR(IF('Labor Projection'!H38=0,'Labor Projection'!F38,(('Labor Projection'!G38/'Labor Projection'!H38)-'Labor Projection'!G38)),"") -> 120 | K38: =IFERROR('Labor Projection'!I38*'Labor Projection'!J38,"") -> 0 | L38: =IFERROR('Labor Projection'!I38+'Labor Projection'!K38,"") -> 120 | M38: =IFERROR('Labor Projection'!L38+'Labor Projection'!G38,"") -> 120 | N38: =IFERROR('Labor Projection'!M38-'Labor Projection'!F38,"") -> 0 | O38: 4740 | P38: =IFERROR('Labor Projection'!Q38-'Labor Projection'!O38,"") -> 0 | Q38: 4740 | S38: =IFERROR('Labor Projection'!L38*'Labor Projection'!$K$1,"") | T38: =IFERROR('Labor Projection'!R38+'Labor Projection'!S38,"") | U38: =IFERROR('Labor Projection'!T38-'Labor Projection'!Q38,"") | V38: =IFERROR(IF('Labor Projection'!D38=0,0,'Labor Projection'!O38/'Labor Projection'!D38),"") -> 39.5 | W38: =IFERROR(IF('Labor Projection'!G38=0,0,'Labor Projection'!R38/'Labor Projection'!G38),"") -> 0 | X38: =IFERROR('Labor Projection'!W38-'Labor Projection'!V38,"") -> -39.5 | Y38: L | Z38: 0050301000
B39: 00401402 - BW- POWER- HOMERUNS | C39: L | D39: 641 | E39: =IFERROR('Labor Projection'!F39-'Labor Projection'!D39,"") -> 0 | F39: 641 | I39: =IFERROR(IF('Labor Projection'!H39=0,'Labor Projection'!F39,(('Labor Projection'!G39/'Labor Projection'!H39)-'Labor Projection'!G39)),"") -> 641 | K39: =IFERROR('Labor Projection'!I39*'Labor Projection'!J39,"") -> 0 | L39: =IFERROR('Labor Projection'!I39+'Labor Projection'!K39,"") -> 641 | M39: =IFERROR('Labor Projection'!L39+'Labor Projection'!G39,"") -> 641 | N39: =IFERROR('Labor Projection'!M39-'Labor Projection'!F39,"") -> 0 | O39: 25320 | P39: =IFERROR('Labor Projection'!Q39-'Labor Projection'!O39,"") -> 0 | Q39: 25320 | S39: =IFERROR('Labor Projection'!L39*'Labor Projection'!$K$1,"") | T39: =IFERROR('Labor Projection'!R39+'Labor Projection'!S39,"") | U39: =IFERROR('Labor Projection'!T39-'Labor Projection'!Q39,"") | V39: =IFERROR(IF('Labor Projection'!D39=0,0,'Labor Projection'!O39/'Labor Projection'!D39),"") -> 39.50078 | W39: =IFERROR(IF('Labor Projection'!G39=0,0,'Labor Projection'!R39/'Labor Projection'!G39),"") -> 0 | X39: =IFERROR('Labor Projection'!W39-'Labor Projection'!V39,"") -> -39.50078 | Y39: L | Z39: 0050301000
B40: 00401403 - BW- POWER- ABOVE CEILING | C40: L | D40: 2093 | E40: =IFERROR('Labor Projection'!F40-'Labor Projection'!D40,"") -> 0 | F40: 2093 | I40: =IFERROR(IF('Labor Projection'!H40=0,'Labor Projection'!F40,(('Labor Projection'!G40/'Labor Projection'!H40)-'Labor Projection'!G40)),"") -> 2093 | K40: =IFERROR('Labor Projection'!I40*'Labor Projection'!J40,"") -> 0 | L40: =IFERROR('Labor Projection'!I40+'Labor Projection'!K40,"") -> 2093 | M40: =IFERROR('Labor Projection'!L40+'Labor Projection'!G40,"") -> 2093 | N40: =IFERROR('Labor Projection'!M40-'Labor Projection'!F40,"") -> 0 | O40: 82674 | P40: =IFERROR('Labor Projection'!Q40-'Labor Projection'!O40,"") -> 0 | Q40: 82674 | S40: =IFERROR('Labor Projection'!L40*'Labor Projection'!$K$1,"") | T40: =IFERROR('Labor Projection'!R40+'Labor Projection'!S40,"") | U40: =IFERROR('Labor Projection'!T40-'Labor Projection'!Q40,"") | V40: =IFERROR(IF('Labor Projection'!D40=0,0,'Labor Projection'!O40/'Labor Projection'!D40),"") -> 39.500239 | W40: =IFERROR(IF('Labor Projection'!G40=0,0,'Labor Projection'!R40/'Labor Projection'!G40),"") -> 0 | X40: =IFERROR('Labor Projection'!W40-'Labor Projection'!V40,"") -> -39.500239 | Y40: L | Z40: 0050301000
B41: 00401404 - WIRING DEVICES- POWER | C41: L | D41: 257 | E41: =IFERROR('Labor Projection'!F41-'Labor Projection'!D41,"") -> 0 | F41: 257 | I41: =IFERROR(IF('Labor Projection'!H41=0,'Labor Projection'!F41,(('Labor Projection'!G41/'Labor Projection'!H41)-'Labor Projection'!G41)),"") -> 257 | K41: =IFERROR('Labor Projection'!I41*'Labor Projection'!J41,"") -> 0 | L41: =IFERROR('Labor Projection'!I41+'Labor Projection'!K41,"") -> 257 | M41: =IFERROR('Labor Projection'!L41+'Labor Projection'!G41,"") -> 257 | N41: =IFERROR('Labor Projection'!M41-'Labor Projection'!F41,"") -> 0 | O41: 10152 | P41: =IFERROR('Labor Projection'!Q41-'Labor Projection'!O41,"") -> 0 | Q41: 10152 | S41: =IFERROR('Labor Projection'!L41*'Labor Projection'!$K$1,"") | T41: =IFERROR('Labor Projection'!R41+'Labor Projection'!S41,"") | U41: =IFERROR('Labor Projection'!T41-'Labor Projection'!Q41,"") | V41: =IFERROR(IF('Labor Projection'!D41=0,0,'Labor Projection'!O41/'Labor Projection'!D41),"") -> 39.501946 | W41: =IFERROR(IF('Labor Projection'!G41=0,0,'Labor Projection'!R41/'Labor Projection'!G41),"") -> 0 | X41: =IFERROR('Labor Projection'!W41-'Labor Projection'!V41,"") -> -39.501946 | Y41: L | Z41: 0050301000
B42: 00405450 - ENGRAVING TAGS | C42: L | D42: 0 | E42: =IFERROR('Labor Projection'!F42-'Labor Projection'!D42,"") -> 0 | F42: 0 | I42: =IFERROR(IF('Labor Projection'!H42=0,'Labor Projection'!F42,(('Labor Projection'!G42/'Labor Projection'!H42)-'Labor Projection'!G42)),"") -> 0 | K42: =IFERROR('Labor Projection'!I42*'Labor Projection'!J42,"") -> 0 | L42: =IFERROR('Labor Projection'!I42+'Labor Projection'!K42,"") -> 0 | M42: =IFERROR('Labor Projection'!L42+'Labor Projection'!G42,"") -> 0 | N42: =IFERROR('Labor Projection'!M42-'Labor Projection'!F42,"") -> 0 | O42: 0 | P42: =IFERROR('Labor Projection'!Q42-'Labor Projection'!O42,"") -> 0 | Q42: 0 | S42: =IFERROR('Labor Projection'!L42*'Labor Projection'!$K$1,"") | T42: =IFERROR('Labor Projection'!R42+'Labor Projection'!S42,"") | U42: =IFERROR('Labor Projection'!T42-'Labor Projection'!Q42,"") | V42: =IFERROR(IF('Labor Projection'!D42=0,0,'Labor Projection'!O42/'Labor Projection'!D42),"") -> 0 | W42: =IFERROR(IF('Labor Projection'!G42=0,0,'Labor Projection'!R42/'Labor Projection'!G42),"") -> 0 | X42: =IFERROR('Labor Projection'!W42-'Labor Projection'!V42,"") -> 0 | Y42: L | Z42: 0050301000
B43: 00405450 - ENGRAVING TAGS | C43: LA | D43: 0 | E43: =IFERROR('Labor Projection'!F43-'Labor Projection'!D43,"") -> 0 | F43: 0 | I43: =IFERROR(IF('Labor Projection'!H43=0,'Labor Projection'!F43,(('Labor Projection'!G43/'Labor Projection'!H43)-'Labor Projection'!G43)),"") -> 0 | K43: =IFERROR('Labor Projection'!I43*'Labor Projection'!J43,"") -> 0 | L43: =IFERROR('Labor Projection'!I43+'Labor Projection'!K43,"") -> 0 | M43: =IFERROR('Labor Projection'!L43+'Labor Projection'!G43,"") -> 0 | N43: =IFERROR('Labor Projection'!M43-'Labor Projection'!F43,"") -> 0 | O43: 0 | P43: =IFERROR('Labor Projection'!Q43-'Labor Projection'!O43,"") -> 0 | Q43: 0 | S43: =IFERROR('Labor Projection'!L43*'Labor Projection'!$K$1,"") | T43: =IFERROR('Labor Projection'!R43+'Labor Projection'!S43,"") | U43: =IFERROR('Labor Projection'!T43-'Labor Projection'!Q43,"") | V43: =IFERROR(IF('Labor Projection'!D43=0,0,'Labor Projection'!O43/'Labor Projection'!D43),"") -> 0 | W43: =IFERROR(IF('Labor Projection'!G43=0,0,'Labor Projection'!R43/'Labor Projection'!G43),"") -> 0 | X43: =IFERROR('Labor Projection'!W43-'Labor Projection'!V43,"") -> 0 | Y43: LA | Z43: 0050301000
B44: 00405450 - ENGRAVING TAGS | C44: LB | D44: 0 | E44: =IFERROR('Labor Projection'!F44-'Labor Projection'!D44,"") -> 0 | F44: 0 | I44: =IFERROR(IF('Labor Projection'!H44=0,'Labor Projection'!F44,(('Labor Projection'!G44/'Labor Projection'!H44)-'Labor Projection'!G44)),"") -> 0 | K44: =IFERROR('Labor Projection'!I44*'Labor Projection'!J44,"") -> 0 | L44: =IFERROR('Labor Projection'!I44+'Labor Projection'!K44,"") -> 0 | M44: =IFERROR('Labor Projection'!L44+'Labor Projection'!G44,"") -> 0 | N44: =IFERROR('Labor Projection'!M44-'Labor Projection'!F44,"") -> 0 | O44: 0 | P44: =IFERROR('Labor Projection'!Q44-'Labor Projection'!O44,"") -> 0 | Q44: 0 | S44: =IFERROR('Labor Projection'!L44*'Labor Projection'!$K$1,"") | T44: =IFERROR('Labor Projection'!R44+'Labor Projection'!S44,"") | U44: =IFERROR('Labor Projection'!T44-'Labor Projection'!Q44,"") | V44: =IFERROR(IF('Labor Projection'!D44=0,0,'Labor Projection'!O44/'Labor Projection'!D44),"") -> 0 | W44: =IFERROR(IF('Labor Projection'!G44=0,0,'Labor Projection'!R44/'Labor Projection'!G44),"") -> 0 | X44: =IFERROR('Labor Projection'!W44-'Labor Projection'!V44,"") -> 0 | Y44: LB | Z44: 0050301000
