Workbook
Name __Complete___YE_Block5: Divisions!$V$16
Name __Complete___YE_Block6: Divisions!$V$16
Name __Complete___YE_Block8: Divisions!$V$16
Name __Complete___YE_Division: Divisions!$V$16
Name __Complete___YE_WIP_ProjectManager: 'Project Managers'!$X$12
Name __Complete_Block5: Divisions!$Q$16
Name __Complete_Block6: Divisions!$Q$16
Name __Complete_Block8: Divisions!$Q$16
Name __Complete_Division: Divisions!$Q$16
Name __Complete_WIP_ProjectManager: 'Project Managers'!$Q$12
Name _CY1_Estimated__Cost__Block8: Divisions!$AD$16
Name _CY1_Estimated__Cost__Division: Divisions!$AD$16
Name _CY1_Estimated__Cost__WIP_ProjectManager: 'Project Managers'!$AG$12
Name _Estimated__Cost__Block5: Divisions!$AD$16
Name _Estimated__Cost__Block6: Divisions!$AD$16
Name _Under__Billing_Block5: Divisions!$O$16
Name _Under__Billing_Block6: Divisions!$O$16
Name _Under__Billing_Block8: Divisions!$O$16
Name _Under__Billing_Division: Divisions!$O$16
Name _Under__Billing_WIP_ProjectManager: 'Project Managers'!$O$12
Name Backlog_Block5: Divisions!$P$16
Name Backlog_Block6: Divisions!$P$16
Name Backlog_Block8: Divisions!$P$16
Name Backlog_Division: Divisions!$P$16
Name Backlog_WIP_ProjectManager: 'Project Managers'!$P$12
Name Billed_Amount_Block5: Divisions!$M$16
Name Billed_Amount_Block6: Divisions!$M$16
Name Billed_Amount_Block8: Divisions!$M$16
Name Billed_Amount_Division: Divisions!$M$16
Name Billed_Amount_WIP_ProjectManager: 'Project Managers'!$M$12
Name Comments_Block5: Divisions!$AO$16
Name Comments_Block6: Divisions!$AO$16
Name Comments_Block8: Divisions!$AO$16
Name Comments_Division: Divisions!$AO$16
Name Comments_WIP_ProjectManager: 'Project Managers'!$AR$12
Name Contract__Amount_Block5: Divisions!$AC$16
Name Contract__Amount_Block6: Divisions!$AC$16
Name Contract_Amount____Block5: Divisions!$AH$16
Name Contract_Amount____Block6: Divisions!$AH$16
Name Contract_Amount__Block5: Divisions!$X$16
Name Contract_Amount__Block6: Divisions!$X$16
Name Cost_to_Date_Block5: Divisions!$J$16
Name Cost_to_Date_Block6: Divisions!$J$16
Name Cost_to_Date_Block8: Divisions!$J$16
Name Cost_to_Date_Division: Divisions!$J$16
Name Cost_to_Date_WIP_ProjectManager: 'Project Managers'!$J$12
Name Current_Contract_Amount_Block5: Divisions!$E$16
Name Current_Contract_Amount_Block6: Divisions!$E$16
Name Current_Contract_Amount_Block8: Divisions!$E$16
Name Current_Contract_Amount_Division: Divisions!$E$16
Name Current_Contract_Amount_WIP_ProjectManager: 'Project Managers'!$E$12
Name CY_Contract_Amount__Block8: Divisions!$X$16
Name CY_Contract_Amount__Division: Divisions!$X$16
Name CY_Contract_Amount__WIP_ProjectManager: 'Project Managers'!$AA$12
Name CY_Estimated_Cost_Block8: Divisions!$Y$16
Name CY_Estimated_Cost_Division: Divisions!$Y$16
Name CY_Estimated_Cost_WIP_ProjectManager: 'Project Managers'!$AB$12
Name CY_GM_____Block8: Divisions!$AA$16
Name CY_GM_____Division: Divisions!$AA$16
Name CY_GM_____WIP_ProjectManager: 'Project Managers'!$AD$12

Sheet Query
A1: WITH subqueryTable0 AS (
A2: SELECT
A3: MAX(table0.CorporateFilter__custom) AS CorporateFilter__custom,
A4: MAX(table0.project_manager) AS Project_Manager__custom,
A5: MAX(table0.project_manager) AS projectmanager__standard,
A6: SUM(table0.GM) AS EStimatedGMPct__custom,
A7: '2025-12-31' AS EOPeriodDate,
A8: table0.New_Job_Number AS ProjectUniqueID
A9: FROM
A10: PHASE_MASTER AS table0
A11: WHERE
A12: (
... A181: ProjectUniqueID

Sheet Project Managers
E7: Estimated | Y7: =YEAR(Divisions!H4) -> 2025 | AE7: =Y7+1 -> 2026 | AJ7: =AE7+1 -> 2027
B8: {=B11} -> Project Manager | C8: {=C11} -> Job Number | D8: {=D11} -> Description | E8: {=E11} -> Current Contract Amount | F8: {=F11} -> Estimated Cost | G8: {=G11} -> Gross Margin | H8: {=H11} -> GM% | I8: {=I11} -> JTD Earned Revenue | ... Y8: {=Y11} -> Prior Period Revised % Complete @ YE | Z8: Revised % Complete @ YE | AA8: Contract Amount | AB8: Estimated Cost | AC8: Gross Margin | AD8: GM % | AE8: Revised % Complete @ YE | AF8: Contract Amount | AG8: Estimated Cost | AH8: Gross Margin | AI8: GM % | AJ8: Revised % Complete @ YE | AK8: Contract Amount | AL8: Estimated Cost | AM8: Gross Margin | AN8: GM % | AO8: Gross Margin | AP8: GM % | AQ8: {=AP11} -> pmestimatedgmpercentage__custom | AR8: {=AR11} -> Comments
B11: Project Manager | C11: Job Number | D11: Description | E11: Current Contract Amount | F11: Estimated Cost | G11: Gross Margin | H11: GM% | I11: JTD Earned Revenue | J11: Cost to Date | K11: Gross Margin to Date | L11: GM % | M11: Billed Amount | N11: Over Billing | O11: (Under) Billing | P11: Backlog | Q11: % Complete | R11: PM Estimated GM % | S11: Prior Period Revised PM Estimated GM % | T11: Revised PM Estimated GM % | U11: Potential Profit | V11: Prior Period Revised Potential Profit | W11: Revised Potential Profit | X11: % Complete @ YE | Y11: Prior Period Revised % Complete @ YE | Z11: Revised % Complete @ YE | AA11: CY Contract Amount | AB11: CY Estimated Cost | AC11: CY Gross Margin | AD11: CY GM % | AE11: RevisedCY1 % Complete | AF11: CY1 Contract Amount | AG11: CY1 Estimated Cost | AH11: CY1 Gross Margin | AI11: CY1GM% | AJ11: CY2 Revised % Complete @ YE | AK11: CY2 Contract Amount | AL11: CY2 Estimated Cost | AM11: CY2 Gross Margin | AN11: CY2 GM % | AO11: estimatedgmpercentage__custom | AP11: pmestimatedgmpercentage__custom | AQ11: percentagecompleteatye__custom | AR11: Comments | AS11: EStimatedGMPct | BT11: Comments
B12: B LIU | C12: 719500 | D12: SWITCH RR NAP 4 | E12: 20845819 | F12: =IFERROR('Project Managers'!E12*(1-'Project Managers'!H12),0) -> 16885113 | G12: =IFERROR('Project Managers'!E12-'Project Managers'!F12,0) -> 3960705.6 | H12: {=IF(ISBLANK('Project Managers'!AO12),'Project Managers'!R12,'Project Managers'!AO12)} -> 0.19 | I12: 20845819 | J12: 16381247 | K12: =IFERROR('Project Managers'!I12-'Project Managers'!J12,0) -> 4464572.5 | L12: =IFERROR('Project Managers'!K12/'Project Managers'!I12,0) -> 0.21417112 | M12: 20845819 | N12: =IFERROR(IF('Project Managers'!M12-'Project Managers'!I12>0,'Project Managers'!M12-'Project Managers'!I12,0),0) -> 0 | O12: =IFERROR(IF('Project Managers'!M12-'Project Managers'!I12<0,'Project Managers'!M12-'Project Managers'!I12,0),0) -> 0 | P12: =IFERROR('Project Managers'!E12-'Project Managers'!I12,0) -> 0 | Q12: =IFERROR(ROUND('Project Managers'!I12/'Project Managers'!E12,4),0) -> 1 | R12: {=IF(ISBLANK('Project Managers'!AP12),IF('Project Managers'!I12<>0,('Project Managers'!I12-'Project Managers'!J12)/'Project Managers'!I12,'Project Managers'!AS12),'Project Managers'!AP12)} -> 0.21 | S12: 0.2149 | T12: 0.2142 | U12: =IFERROR(-('Project Managers'!I12-('Project Managers'!J12/(1-'Project Managers'!R12))),0) -> -110063.92 | V12: -690.43765 | W12: =IFERROR(-('Project Managers'!I12-('Project Managers'!J12/(1-'Project Managers'!T12))),0) -> 766.02709 | X12: =IFERROR(IF('Project Managers'!AQ12="",1,'Project Managers'!AQ12),0) -> 1 | Y12: 1 | Z12: 1 | AA12: =IFERROR(IF('Project Managers'!Z12='Project Managers'!Q12,0,(('Project Managers'!Z12*'Project Managers'!E12)-'Project Managers'!I12)),0) -> 0 | AB12: =IFERROR(IF('Project Managers'!Z12='Project Managers'!Q12,0,('Project Managers'!AA12-('Project Managers'!AA12*'Project Managers'!L12))),0) -> 0 | AC12: =IFERROR('Project Managers'!AA12-'Project Managers'!AB12,0) -> 0 | AD12: =IFERROR('Project Managers'!AC12/'Project Managers'!AA12,0) -> 0 | AE12: =IFERROR(IF('Project Managers'!Z12<1,1,0),0) -> 0 | AF12: =IFERROR(IF('Project Managers'!AE12=0,0,('Project Managers'!AE12*'Project Managers'!E12)-'Project Managers'!I12-'Project Managers'!AA12),0) -> 0 | AG12: =IFERROR(IF('Project Managers'!AE12='Project Managers'!V12,0,('Project Managers'!AF12-('Project Managers'!AF12*'Project Managers'!L12))),0) -> 0 | AH12: =IFERROR('Project Managers'!AF12-'Project Managers'!AG12,0) -> 0 | AI12: =IFERROR('Project Managers'!AH12/'Project Managers'!AF12,0) -> 0 | AK12: =IFERROR(IF('Project Managers'!AJ12=0,0,('Project Managers'!AJ12*'Project Managers'!E12)-'Project Managers'!I12-'Project Managers'!AA12-'Project Managers'!AF12),0) -> 0 | AL12: =IFERROR(IF('Project Managers'!AJ12='Project Managers'!V12,0,('Project Managers'!AK12-('Project Managers'!AK12*'Project Managers'!L12))),0) -> 0 | AM12: =IFERROR('Project Managers'!AK12-'Project Managers'!AL12,0) -> 0 | AN12: =IFERROR('Project Managers'!AM12/'Project Managers'!AK12,0) -> 0 | AO12: 0.19 | AP12: 0.21
B13: B LIU | C13: 722320 | D13: SPACEX DIRECT WORK | E13: 128026.07 | F13: =IFERROR('Project Managers'!E13*(1-'Project Managers'!H13),0) -> 106193.44 | G13: =IFERROR('Project Managers'!E13-'Project Managers'!F13,0) -> 21832.631 | H13: {=IF(ISBLANK('Project Managers'!AO13),'Project Managers'!R13,'Project Managers'!AO13)} -> 0.1705327 | I13: 124814.07 | J13: 103529.19 | K13: =IFERROR('Project Managers'!I13-'Project Managers'!J13,0) -> 21284.88 | L13: =IFERROR('Project Managers'!K13/'Project Managers'!I13,0) -> 0.1705327 | M13: 124814.07 | N13: =IFERROR(IF('Project Managers'!M13-'Project Managers'!I13>0,'Project Managers'!M13-'Project Managers'!I13,0),0) -> 0 | O13: =IFERROR(IF('Project Managers'!M13-'Project Managers'!I13<0,'Project Managers'!M13-'Project Managers'!I13,0),0) -> 0 | P13: =IFERROR('Project Managers'!E13-'Project Managers'!I13,0) -> 3212 | Q13: =IFERROR(ROUND('Project Managers'!I13/'Project Managers'!E13,4),0) -> 0.9749 | R13: =IF(ISBLANK('Project Managers'!AP13),IF('Project Managers'!I13<>0,('Project Managers'!I13-'Project Managers'!J13)/'Project Managers'!I13,'Project Managers'!AS13),'Project Managers'!AP13) -> 0.1705327 | S13: 0.15 | T13: 0.15 | U13: =IFERROR(-('Project Managers'!I13-('Project Managers'!J13/(1-'Project Managers'!R13))),0) -> 0 | V13: -3850.67 | W13: =IFERROR(-('Project Managers'!I13-('Project Managers'!J13/(1-'Project Managers'!T13))),0) -> -3015.0229 | X13: =IFERROR(IF('Project Managers'!AQ13="",1,'Project Managers'!AQ13),0) -> 1 | Y13: 1 | Z13: 1 | AA13: =IFERROR(IF('Project Managers'!Z13='Project Managers'!Q13,0,(('Project Managers'!Z13*'Project Managers'!E13)-'Project Managers'!I13)),0) -> 3212 | AB13: =IFERROR(IF('Project Managers'!Z13='Project Managers'!Q13,0,('Project Managers'!AA13-('Project Managers'!AA13*'Project Managers'!L13))),0) -> 2664.249 | AC13: =IFERROR('Project Managers'!AA13-'Project Managers'!AB13,0) -> 547.75102 | AD13: =IFERROR('Project Managers'!AC13/'Project Managers'!AA13,0) -> 0.1705327 | AE13: =IFERROR(IF('Project Managers'!Z13<1,1,0),0) -> 0 | AF13: =IFERROR(IF('Project Managers'!AE13=0,0,('Project Managers'!AE13*'Project Managers'!E13)-'Project Managers'!I13-'Project Managers'!AA13),0) -> 0 | AG13: =IFERROR(IF('Project Managers'!AE13='Project Managers'!V13,0,('Project Managers'!AF13-('Project Managers'!AF13*'Project Managers'!L13))),0) -> 0 | AH13: =IFERROR('Project Managers'!AF13-'Project Managers'!AG13,0) -> 0 | AI13: =IFERROR('Project Managers'!AH13/'Project Managers'!AF13,0) -> 0 | AK13: =IFERROR(IF('Project Managers'!AJ13=0,0,('Project Managers'!AJ13*'Project Managers'!E13)-'Project Managers'!I13-'Project Managers'!AA13-'Project Managers'!AF13),0) -> 0 | AL13: =IFERROR(IF('Project Managers'!AJ13='Project Managers'!V13,0,('Project Managers'!AK13-('Project Managers'!AK13*'Project Managers'!L13))),0) -> 0 | AM13: =IFERROR('Project Managers'!AK13-'Project Managers'!AL13,0) -> 0 | AN13: =IFERROR('Project Managers'!AM13/'Project Managers'!AK13,0) -> 0 | AS13: 0.15
B14: Subtotal of B LIU | C14: - | D14: - | E14: =SUBTOTAL(9,E12:E13) -> 20973845 | F14: =SUBTOTAL(9,F12:F13) -> 16991307 | G14: =SUBTOTAL(9,G12:G13) -> 3982538.2 | H14: {=IF(ISBLANK('Project Managers'!AO14),'Project Managers'!R14,'Project Managers'!AO14)} -> - | I14: =SUBTOTAL(9,I12:I13) -> 20970633 | J14: =SUBTOTAL(9,J12:J13) -> 16484776 | K14: =SUBTOTAL(9,K12:K13) -> 4485857.4 | L14: =IFERROR('Project Managers'!K14/'Project Managers'!I14,0) -> 0.21391139 | M14: =SUBTOTAL(9,M12:M13) -> 20970633 | N14: =SUBTOTAL(9,N12:N13) -> 0 | O14: =SUBTOTAL(9,O12:O13) -> 0 | P14: =SUBTOTAL(9,P12:P13) -> 3212 | Q14: =IFERROR(ROUND('Project Managers'!I14/'Project Managers'!E14,4),0) -> 0.9998 | R14: - | S14: - | T14: - | U14: =SUBTOTAL(9,U12:U13) -> -110063.92 | V14: =SUBTOTAL(9,V12:V13) -> -4541.1077 | W14: =SUBTOTAL(9,W12:W13) -> -2248.9959 | X14: - | Y14: - | Z14: - | AA14: =SUBTOTAL(9,AA12:AA13) -> 3212 | AB14: =SUBTOTAL(9,AB12:AB13) -> 2664.249 | AC14: =IFERROR('Project Managers'!AA14-'Project Managers'!AB14,0) -> 547.75102 | AD14: =IFERROR('Project Managers'!AC14/'Project Managers'!AA14,0) -> 0.1705327 | AE14: =IFERROR(IF('Project Managers'!Z14<1,1,0),0) -> 0 | AF14: =SUBTOTAL(9,AF12:AF13) -> 0 | AG14: =SUBTOTAL(9,AG12:AG13) -> 0 | AH14: =SUBTOTAL(9,AH12:AH13) -> 0 | AI14: =IFERROR('Project Managers'!AH14/'Project Managers'!AF14,0) -> 0 | AJ14: - | AK14: =SUBTOTAL(9,AK12:AK13) -> 0 | AL14: =SUBTOTAL(9,AL12:AL13) -> 0 | AM14: =SUBTOTAL(9,AM12:AM13) -> 0 | AN14: =IFERROR('Project Managers'!AM14/'Project Managers'!AK14,0) -> 0 | AO14: - | AP14: - | AQ14: - | AR14: - | AS14: -
B15: B ONTIVEROS | C15: 722210 | D15: LIBERTY HILL HS #2 | E15: 11473198 | F15: =IFERROR('Project Managers'!E15*(1-'Project Managers'!H15),0) -> 9522754.3 | G15: =IFERROR('Project Managers'!E15-'Project Managers'!F15,0) -> 1950443.7 | H15: {=IF(ISBLANK('Project Managers'!AO15),'Project Managers'!R15,'Project Managers'!AO15)} -> 0.17 | I15: 10565813 | J15: 8976901.2 | K15: =IFERROR('Project Managers'!I15-'Project Managers'!J15,0) -> 1588911.5 | L15: =IFERROR('Project Managers'!K15/'Project Managers'!I15,0) -> 0.15038233 | M15: 10673409 | N15: =IFERROR(IF('Project Managers'!M15-'Project Managers'!I15>0,'Project Managers'!M15-'Project Managers'!I15,0),0) -> 107596.05 | O15: =IFERROR(IF('Project Managers'!M15-'Project Managers'!I15<0,'Project Managers'!M15-'Project Managers'!I15,0),0) -> 0 | P15: =IFERROR('Project Managers'!E15-'Project Managers'!I15,0) -> 907385.3 | Q15: =IFERROR(ROUND('Project Managers'!I15/'Project Managers'!E15,4),0) -> 0.9209 | R15: {=IF(ISBLANK('Project Managers'!AP15),IF('Project Managers'!I15<>0,('Project Managers'!I15-'Project Managers'!J15)/'Project Managers'!I15,'Project Managers'!AS15),'Project Managers'!AP15)} -> 0.19 | S15: 0.15 | T15: 0.15 | U15: =IFERROR(-('Project Managers'!I15-('Project Managers'!J15/(1-'Project Managers'!R15))),0) -> 516781.36 | V15: -4632.4106 | W15: =IFERROR(-('Project Managers'!I15-('Project Managers'!J15/(1-'Project Managers'!T15))),0) -> -4752.4765 | X15: =IFERROR(IF('Project Managers'!AQ15="",1,'Project Managers'!AQ15),0) -> 1 | Y15: 0.9898 | Z15: 0.87 | AA15: =IFERROR(IF('Project Managers'!Z15='Project Managers'!Q15,0,(('Project Managers'!Z15*'Project Managers'!E15)-'Project Managers'!I15)),0) -> -584130.44 | AB15: =IFERROR(IF('Project Managers'!Z15='Project Managers'!Q15,0,('Project Managers'!AA15-('Project Managers'!AA15*'Project Managers'!L15))),0) -> -496287.54 | AC15: =IFERROR('Project Managers'!AA15-'Project Managers'!AB15,0) -> -87842.895 | AD15: =IFERROR('Project Managers'!AC15/'Project Managers'!AA15,0) -> 0.15038233 | AE15: =IFERROR(IF('Project Managers'!Z15<1,1,0),0) -> 1 | AF15: =IFERROR(IF('Project Managers'!AE15=0,0,('Project Managers'!AE15*'Project Managers'!E15)-'Project Managers'!I15-'Project Managers'!AA15),0) -> 1491515.7 | AG15: =IFERROR(IF('Project Managers'!AE15='Project Managers'!V15,0,('Project Managers'!AF15-('Project Managers'!AF15*'Project Managers'!L15))),0) -> 1267218.1 | AH15: =IFERROR('Project Managers'!AF15-'Project Managers'!AG15,0) -> 224297.61 | AI15: =IFERROR('Project Managers'!AH15/'Project Managers'!AF15,0) -> 0.15038233 | AK15: =IFERROR(IF('Project Managers'!AJ15=0,0,('Project Managers'!AJ15*'Project Managers'!E15)-'Project Managers'!I15-'Project Managers'!AA15-'Project Managers'!AF15),0) -> 0 | AL15: =IFERROR(IF('Project Managers'!AJ15='Project Managers'!V15,0,('Project Managers'!AK15-('Project Managers'!AK15*'Project Managers'!L15))),0) -> 0 | AM15: =IFERROR('Project Managers'!AK15-'Project Managers'!AL15,0) -> 0 | AN15: =IFERROR('Project Managers'!AM15/'Project Managers'!AK15,0) -> 0 | AO15: 0.17 | AP15: 0.19 | AS15: 0.3
B16: B ONTIVEROS | C16: 722450 | D16: VALERO AUSTIN PAC OFFICE | E16: 404338.1 | F16: =IFERROR('Project Managers'!E16*(1-'Project Managers'!H16),0) -> 337510.95 | G16: =IFERROR('Project Managers'!E16-'Project Managers'!F16,0) -> 66827.152 | H16: {=IF(ISBLANK('Project Managers'!AO16),'Project Managers'!R16,'Project Managers'!AO16)} -> 0.16527543 | I16: 395116.39 | J16: 329813.36 | K16: =IFERROR('Project Managers'!I16-'Project Managers'!J16,0) -> 65303.03 | L16: =IFERROR('Project Managers'!K16/'Project Managers'!I16,0) -> 0.16527543 | M16: 404338.1 | N16: =IFERROR(IF('Project Managers'!M16-'Project Managers'!I16>0,'Project Managers'!M16-'Project Managers'!I16,0),0) -> 9221.71 | O16: =IFERROR(IF('Project Managers'!M16-'Project Managers'!I16<0,'Project Managers'!M16-'Project Managers'!I16,0),0) -> 0 | P16: =IFERROR('Project Managers'!E16-'Project Managers'!I16,0) -> 9221.71 | Q16: =IFERROR(ROUND('Project Managers'!I16/'Project Managers'!E16,4),0) -> 0.9772 | R16: =IF(ISBLANK('Project Managers'!AP16),IF('Project Managers'!I16<>0,('Project Managers'!I16-'Project Managers'!J16)/'Project Managers'!I16,'Project Managers'!AS16),'Project Managers'!AP16) -> 0.16527543 | S16: 0.17 | T16: 0.17 | U16: =IFERROR(-('Project Managers'!I16-('Project Managers'!J16/(1-'Project Managers'!R16))),0) -> 0 | V16: 9254.1282 | W16: =IFERROR(-('Project Managers'!I16-('Project Managers'!J16/(1-'Project Managers'!T16))),0) -> 2249.104 | X16: =IFERROR(IF('Project Managers'!AQ16="",1,'Project Managers'!AQ16),0) -> 1 | Y16: 1 | Z16: 1 | AA16: =IFERROR(IF('Project Managers'!Z16='Project Managers'!Q16,0,(('Project Managers'!Z16*'Project Managers'!E16)-'Project Managers'!I16)),0) -> 9221.71 | AB16: =IFERROR(IF('Project Managers'!Z16='Project Managers'!Q16,0,('Project Managers'!AA16-('Project Managers'!AA16*'Project Managers'!L16))),0) -> 7697.5879 | AC16: =IFERROR('Project Managers'!AA16-'Project Managers'!AB16,0) -> 1524.1221 | AD16: =IFERROR('Project Managers'!AC16/'Project Managers'!AA16,0) -> 0.16527543 | AE16: =IFERROR(IF('Project Managers'!Z16<1,1,0),0) -> 0 | AF16: =IFERROR(IF('Project Managers'!AE16=0,0,('Project Managers'!AE16*'Project Managers'!E16)-'Project Managers'!I16-'Project Managers'!AA16),0) -> 0 | AG16: =IFERROR(IF('Project Managers'!AE16='Project Managers'!V16,0,('Project Managers'!AF16-('Project Managers'!AF16*'Project Managers'!L16))),0) -> 0 | AH16: =IFERROR('Project Managers'!AF16-'Project Managers'!AG16,0) -> 0 | AI16: =IFERROR('Project Managers'!AH16/'Project Managers'!AF16,0) -> 0 | AK16: =IFERROR(IF('Project Managers'!AJ16=0,0,('Project Managers'!AJ16*'Project Managers'!E16)-'Project Managers'!I16-'Project Managers'!AA16-'Project Managers'!AF16),0) -> 0 | AL16: =IFERROR(IF('Project Managers'!AJ16='Project Managers'!V16,0,('Project Managers'!AK16-('Project Managers'!AK16*'Project Managers'!L16))),0) -> 0 | AM16: =IFERROR('Project Managers'!AK16-'Project Managers'!AL16,0) -> 0 | AN16: =IFERROR('Project Managers'!AM16/'Project Managers'!AK16,0) -> 0
B17: B ONTIVEROS | C17: 722500 | D17: CORR OSP ADMIN & REC | E17: 9526861 | F17: =IFERROR('Project Managers'!E17*(1-'Project Managers'!H17),0) -> 7906107.9 | G17: =IFERROR('Project Managers'!E17-'Project Managers'!F17,0) -> 1620753.1 | H17: {=IF(ISBLANK('Project Managers'!AO17),'Project Managers'!R17,'Project Managers'!AO17)} -> 0.17012456 | I17: 233598.07 | J17: 193857.3 | K17: =IFERROR('Project Managers'!I17-'Project Managers'!J17,0) -> 39740.77 | L17: =IFERROR('Project Managers'!K17/'Project Managers'!I17,0) -> 0.17012456 | M17: 268250 | N17: =IFERROR(IF('Project Managers'!M17-'Project Managers'!I17>0,'Project Managers'!M17-'Project Managers'!I17,0),0) -> 34651.93 | O17: =IFERROR(IF('Project Managers'!M17-'Project Managers'!I17<0,'Project Managers'!M17-'Project Managers'!I17,0),0) -> 0 | P17: =IFERROR('Project Managers'!E17-'Project Managers'!I17,0) -> 9293262.9 | Q17: =IFERROR(ROUND('Project Managers'!I17/'Project Managers'!E17,4),0) -> 0.0245 | R17: =IF(ISBLANK('Project Managers'!AP17),IF('Project Managers'!I17<>0,('Project Managers'!I17-'Project Managers'!J17)/'Project Managers'!I17,'Project Managers'!AS17),'Project Managers'!AP17) -> 0.17012456 | S17: 0.15 | T17: 0.17 | U17: =IFERROR(-('Project Managers'!I17-('Project Managers'!J17/(1-'Project Managers'!R17))),0) -> 0 | V17: -2771.5918 | W17: =IFERROR(-('Project Managers'!I17-('Project Managers'!J17/(1-'Project Managers'!T17))),0) -> -35.057952 | X17: =IFERROR(IF('Project Managers'!AQ17="",1,'Project Managers'!AQ17),0) -> 1 | Y17: 0.1111 | Z17: 0.05 | AA17: =IFERROR(IF('Project Managers'!Z17='Project Managers'!Q17,0,(('Project Managers'!Z17*'Project Managers'!E17)-'Project Managers'!I17)),0) -> 242744.98 | AB17: =IFERROR(IF('Project Managers'!Z17='Project Managers'!Q17,0,('Project Managers'!AA17-('Project Managers'!AA17*'Project Managers'!L17))),0) -> 201448.1 | AC17: =IFERROR('Project Managers'!AA17-'Project Managers'!AB17,0) -> 41296.884 | AD17: =IFERROR('Project Managers'!AC17/'Project Managers'!AA17,0) -> 0.17012456 | AE17: =IFERROR(IF('Project Managers'!Z17<1,1,0),0) -> 1 | AF17: =IFERROR(IF('Project Managers'!AE17=0,0,('Project Managers'!AE17*'Project Managers'!E17)-'Project Managers'!I17-'Project Managers'!AA17),0) -> 9050517.9 | AG17: =IFERROR(IF('Project Managers'!AE17='Project Managers'!V17,0,('Project Managers'!AF17-('Project Managers'!AF17*'Project Managers'!L17))),0) -> 7510802.5 | AH17: =IFERROR('Project Managers'!AF17-'Project Managers'!AG17,0) -> 1539715.4 | AI17: =IFERROR('Project Managers'!AH17/'Project Managers'!AF17,0) -> 0.17012456 | AJ17: 1 | AK17: =IFERROR(IF('Project Managers'!AJ17=0,0,('Project Managers'!AJ17*'Project Managers'!E17)-'Project Managers'!I17-'Project Managers'!AA17-'Project Managers'!AF17),0) -> 0 | AL17: =IFERROR(IF('Project Managers'!AJ17='Project Managers'!V17,0,('Project Managers'!AK17-('Project Managers'!AK17*'Project Managers'!L17))),0) -> 0 | AM17: =IFERROR('Project Managers'!AK17-'Project Managers'!AL17,0) -> 0 | AN17: =IFERROR('Project Managers'!AM17/'Project Managers'!AK17,0) -> 0 | AS17: 0.17
B18: Subtotal of B ONTIVEROS | C18: - | D18: - | E18: =SUBTOTAL(9,E15:E17) -> 21404397 | F18: =SUBTOTAL(9,F15:F17) -> 17766373 | G18: =SUBTOTAL(9,G15:G17) -> 3638023.9 | H18: {=IF(ISBLANK('Project Managers'!AO18),'Project Managers'!R18,'Project Managers'!AO18)} -> - | I18: =SUBTOTAL(9,I15:I17) -> 11194527 | J18: =SUBTOTAL(9,J15:J17) -> 9500571.8 | K18: =SUBTOTAL(9,K15:K17) -> 1693955.3 | L18: =IFERROR('Project Managers'!K18/'Project Managers'!I18,0) -> 0.15131995 | M18: =SUBTOTAL(9,M15:M17) -> 11345997 | N18: =SUBTOTAL(9,N15:N17) -> 151469.69 | O18: =SUBTOTAL(9,O15:O17) -> 0 | P18: =SUBTOTAL(9,P15:P17) -> 10209870 | Q18: =IFERROR(ROUND('Project Managers'!I18/'Project Managers'!E18,4),0) -> 0.523 | R18: - | S18: - | T18: - | U18: =SUBTOTAL(9,U15:U17) -> 516781.36 | V18: =SUBTOTAL(9,V15:V17) -> 1850.1258 | W18: =SUBTOTAL(9,W15:W17) -> -2538.4304 | X18: - | Y18: - | Z18: - | AA18: =SUBTOTAL(9,AA15:AA17) -> -332163.75 | AB18: =SUBTOTAL(9,AB15:AB17) -> -287141.86 | AC18: =IFERROR('Project Managers'!AA18-'Project Managers'!AB18,0) -> -45021.889 | AD18: =IFERROR('Project Managers'!AC18/'Project Managers'!AA18,0) -> 0.13554125 | AE18: =IFERROR(IF('Project Managers'!Z18<1,1,0),0) -> 0 | AF18: =SUBTOTAL(9,AF15:AF17) -> 10542034 | AG18: =SUBTOTAL(9,AG15:AG17) -> 8778020.7 | AH18: =SUBTOTAL(9,AH15:AH17) -> 1764013 | AI18: =IFERROR('Project Managers'!AH18/'Project Managers'!AF18,0) -> 0.16733138 | AJ18: - | AK18: =SUBTOTAL(9,AK15:AK17) -> 0 | AL18: =SUBTOTAL(9,AL15:AL17) -> 0 | AM18: =SUBTOTAL(9,AM15:AM17) -> 0 | AN18: =IFERROR('Project Managers'!AM18/'Project Managers'!AK18,0) -> 0 | AO18: - | AP18: - | AQ18: - | AR18: - | AS18: -
B19: D CASTANEDA | C19: 722400 | D19: WILCO JUVENILE JUSTICE | E19: 10936332 | F19: =IFERROR('Project Managers'!E19*(1-'Project Managers'!H19),0) -> 8858428.7 | G19: =IFERROR('Project Managers'!E19-'Project Managers'!F19,0) -> 2077903 | H19: {=IF(ISBLANK('Project Managers'!AO19),'Project Managers'!R19,'Project Managers'!AO19)} -> 0.19 | I19: 2811002.6 | J19: 2342502.2 | K19: =IFERROR('Project Managers'!I19-'Project Managers'!J19,0) -> 468500.46 | L19: =IFERROR('Project Managers'!K19/'Project Managers'!I19,0) -> 0.16666667 | M19: 3561220.1 | N19: =IFERROR(IF('Project Managers'!M19-'Project Managers'!I19>0,'Project Managers'!M19-'Project Managers'!I19,0),0) -> 750217.48 | O19: =IFERROR(IF('Project Managers'!M19-'Project Managers'!I19<0,'Project Managers'!M19-'Project Managers'!I19,0),0) -> 0 | P19: =IFERROR('Project Managers'!E19-'Project Managers'!I19,0) -> 8125329.1 | Q19: =IFERROR(ROUND('Project Managers'!I19/'Project Managers'!E19,4),0) -> 0.257 | R19: {=IF(ISBLANK('Project Managers'!AP19),IF('Project Managers'!I19<>0,('Project Managers'!I19-'Project Managers'!J19)/'Project Managers'!I19,'Project Managers'!AS19),'Project Managers'!AP19)} -> 0.18 | S19: 0.17 | T19: 0.18 | U19: =IFERROR(-('Project Managers'!I19-('Project Managers'!J19/(1-'Project Managers'!R19))),0) -> 45707.338 | V19: 9491.6304 | W19: =IFERROR(-('Project Managers'!I19-('Project Managers'!J19/(1-'Project Managers'!T19))),0) -> 45707.338 | X19: =IFERROR(IF('Project Managers'!AQ19="",1,'Project Managers'!AQ19),0) -> 1 | Y19: 0.3337 | Z19: 0.26 | AA19: =IFERROR(IF('Project Managers'!Z19='Project Managers'!Q19,0,(('Project Managers'!Z19*'Project Managers'!E19)-'Project Managers'!I19)),0) -> 32443.6 | AB19: =IFERROR(IF('Project Managers'!Z19='Project Managers'!Q19,0,('Project Managers'!AA19-('Project Managers'!AA19*'Project Managers'!L19))),0) -> 27036.333 | AC19: =IFERROR('Project Managers'!AA19-'Project Managers'!AB19,0) -> 5407.2668 | AD19: =IFERROR('Project Managers'!AC19/'Project Managers'!AA19,0) -> 0.16666667 | AE19: =IFERROR(IF('Project Managers'!Z19<1,1,0),0) -> 1 | AF19: =IFERROR(IF('Project Managers'!AE19=0,0,('Project Managers'!AE19*'Project Managers'!E19)-'Project Managers'!I19-'Project Managers'!AA19),0) -> 8092885.5 | AG19: =IFERROR(IF('Project Managers'!AE19='Project Managers'!V19,0,('Project Managers'!AF19-('Project Managers'!AF19*'Project Managers'!L19))),0) -> 6744071.2 | AH19: =IFERROR('Project Managers'!AF19-'Project Managers'!AG19,0) -> 1348814.3 | AI19: =IFERROR('Project Managers'!AH19/'Project Managers'!AF19,0) -> 0.16666667 | AJ19: 1 | AK19: =IFERROR(IF('Project Managers'!AJ19=0,0,('Project Managers'!AJ19*'Project Managers'!E19)-'Project Managers'!I19-'Project Managers'!AA19-'Project Managers'!AF19),0) -> 0 | AL19: =IFERROR(IF('Project Managers'!AJ19='Project Managers'!V19,0,('Project Managers'!AK19-('Project Managers'!AK19*'Project Managers'!L19))),0) -> 0 | AM19: =IFERROR('Project Managers'!AK19-'Project Managers'!AL19,0) -> 0 | AN19: =IFERROR('Project Managers'!AM19/'Project Managers'!AK19,0) -> 0 | AO19: 0.19 | AP19: 0.18 | AS19: 0.167
B20: D CASTANEDA | C20: 722520 | D20: SPACE X CLEANROOM-HODESS | E20: 8053000 | F20: =IFERROR('Project Managers'!E20*(1-'Project Managers'!H20),0) -> 6682987.7 | G20: =IFERROR('Project Managers'!E20-'Project Managers'!F20,0) -> 1370012.3 | H20: {=IF(ISBLANK('Project Managers'!AO20),'Project Managers'!R20,'Project Managers'!AO20)} -> 0.17012447 | I20: 886097.52 | J20: 735350.65 | K20: =IFERROR('Project Managers'!I20-'Project Managers'!J20,0) -> 150746.87 | L20: =IFERROR('Project Managers'!K20/'Project Managers'!I20,0) -> 0.17012447 | M20: 1670850 | N20: =IFERROR(IF('Project Managers'!M20-'Project Managers'!I20>0,'Project Managers'!M20-'Project Managers'!I20,0),0) -> 784752.48 | O20: =IFERROR(IF('Project Managers'!M20-'Project Managers'!I20<0,'Project Managers'!M20-'Project Managers'!I20,0),0) -> 0 | P20: =IFERROR('Project Managers'!E20-'Project Managers'!I20,0) -> 7166902.5 | Q20: =IFERROR(ROUND('Project Managers'!I20/'Project Managers'!E20,4),0) -> 0.11 | R20: =IF(ISBLANK('Project Managers'!AP20),IF('Project Managers'!I20<>0,('Project Managers'!I20-'Project Managers'!J20)/'Project Managers'!I20,'Project Managers'!AS20),'Project Managers'!AP20) -> 0.17012447 | S20: 0.15 | T20: 0.2 | U20: =IFERROR(-('Project Managers'!I20-('Project Managers'!J20/(1-'Project Managers'!R20))),0) -> 0 | V20: 3675.7847 | W20: =IFERROR(-('Project Managers'!I20-('Project Managers'!J20/(1-'Project Managers'!T20))),0) -> 33090.792 | X20: =IFERROR(IF('Project Managers'!AQ20="",1,'Project Managers'!AQ20),0) -> 1 | Y20: 0.2159 | Z20: 0.25 | AA20: =IFERROR(IF('Project Managers'!Z20='Project Managers'!Q20,0,(('Project Managers'!Z20*'Project Managers'!E20)-'Project Managers'!I20)),0) -> 1127152.5 | AB20: =IFERROR(IF('Project Managers'!Z20='Project Managers'!Q20,0,('Project Managers'!AA20-('Project Managers'!AA20*'Project Managers'!L20))),0) -> 935396.26 | AC20: =IFERROR('Project Managers'!AA20-'Project Managers'!AB20,0) -> 191756.22 | AD20: =IFERROR('Project Managers'!AC20/'Project Managers'!AA20,0) -> 0.17012447 | AE20: =IFERROR(IF('Project Managers'!Z20<1,1,0),0) -> 1 | AF20: =IFERROR(IF('Project Managers'!AE20=0,0,('Project Managers'!AE20*'Project Managers'!E20)-'Project Managers'!I20-'Project Managers'!AA20),0) -> 6039750 | AG20: =IFERROR(IF('Project Managers'!AE20='Project Managers'!V20,0,('Project Managers'!AF20-('Project Managers'!AF20*'Project Managers'!L20))),0) -> 5012240.7 | AH20: =IFERROR('Project Managers'!AF20-'Project Managers'!AG20,0) -> 1027509.3 | AI20: =IFERROR('Project Managers'!AH20/'Project Managers'!AF20,0) -> 0.17012447 | AK20: =IFERROR(IF('Project Managers'!AJ20=0,0,('Project Managers'!AJ20*'Project Managers'!E20)-'Project Managers'!I20-'Project Managers'!AA20-'Project Managers'!AF20),0) -> 0 | AL20: =IFERROR(IF('Project Managers'!AJ20='Project Managers'!V20,0,('Project Managers'!AK20-('Project Managers'!AK20*'Project Managers'!L20))),0) -> 0 | AM20: =IFERROR('Project Managers'!AK20-'Project Managers'!AL20,0) -> 0 | AN20: =IFERROR('Project Managers'!AM20/'Project Managers'!AK20,0) -> 0 | AS20: 0.17
B21: Subtotal of D CASTANEDA | C21: - | D21: - | E21: =SUBTOTAL(9,E19:E20) -> 18989332 | F21: =SUBTOTAL(9,F19:F20) -> 15541416 | G21: =SUBTOTAL(9,G19:G20) -> 3447915.4 | H21: {=IF(ISBLANK('Project Managers'!AO21),'Project Managers'!R21,'Project Managers'!AO21)} -> - | I21: =SUBTOTAL(9,I19:I20) -> 3697100.2 | J21: =SUBTOTAL(9,J19:J20) -> 3077852.8 | K21: =SUBTOTAL(9,K19:K20) -> 619247.33 | L21: =IFERROR('Project Managers'!K21/'Project Managers'!I21,0) -> 0.16749542 | M21: =SUBTOTAL(9,M19:M20) -> 5232070.1 | N21: =SUBTOTAL(9,N19:N20) -> 1534970 | O21: =SUBTOTAL(9,O19:O20) -> 0 | P21: =SUBTOTAL(9,P19:P20) -> 15292232 | Q21: =IFERROR(ROUND('Project Managers'!I21/'Project Managers'!E21,4),0) -> 0.1947 | R21: - | S21: - | T21: - | U21: =SUBTOTAL(9,U19:U20) -> 45707.338 | V21: =SUBTOTAL(9,V19:V20) -> 13167.415 | W21: =SUBTOTAL(9,W19:W20) -> 78798.13 | X21: - | Y21: - | Z21: - | AA21: =SUBTOTAL(9,AA19:AA20) -> 1159596.1 | AB21: =SUBTOTAL(9,AB19:AB20) -> 962432.6 | AC21: =IFERROR('Project Managers'!AA21-'Project Managers'!AB21,0) -> 197163.48 | AD21: =IFERROR('Project Managers'!AC21/'Project Managers'!AA21,0) -> 0.17002773 | AE21: =IFERROR(IF('Project Managers'!Z21<1,1,0),0) -> 0 | AF21: =SUBTOTAL(9,AF19:AF20) -> 14132635 | AG21: =SUBTOTAL(9,AG19:AG20) -> 11756312 | AH21: =SUBTOTAL(9,AH19:AH20) -> 2376323.6 | AI21: =IFERROR('Project Managers'!AH21/'Project Managers'!AF21,0) -> 0.1681444 | AJ21: - | AK21: =SUBTOTAL(9,AK19:AK20) -> 0 | AL21: =SUBTOTAL(9,AL19:AL20) -> 0 | AM21: =SUBTOTAL(9,AM19:AM20) -> 0 | AN21: =IFERROR('Project Managers'!AM21/'Project Managers'!AK21,0) -> 0 | AO21: - | AP21: - | AQ21: - | AR21: - | AS21: -
B22: K HERNANDEZ | C22: 710045 | D22: ZILKER BARTON SPRINGS BAT | E22: 1484896.8 | F22: =IFERROR('Project Managers'!E22*(1-'Project Managers'!H22),0) -> 1158219.5 | G22: =IFERROR('Project Managers'!E22-'Project Managers'!F22,0) -> 326677.3 | H22: {=IF(ISBLANK('Project Managers'!AO22),'Project Managers'!R22,'Project Managers'!AO22)} -> 0.22 | I22: 1484896.8 | J22: 1465800.4 | K22: =IFERROR('Project Managers'!I22-'Project Managers'!J22,0) -> 19096.46 | L22: =IFERROR('Project Managers'!K22/'Project Managers'!I22,0) -> 0.012860463 | M22: 1484896.8 | N22: =IFERROR(IF('Project Managers'!M22-'Project Managers'!I22>0,'Project Managers'!M22-'Project Managers'!I22,0),0) -> 0 | O22: =IFERROR(IF('Project Managers'!M22-'Project Managers'!I22<0,'Project Managers'!M22-'Project Managers'!I22,0),0) -> 0 | P22: =IFERROR('Project Managers'!E22-'Project Managers'!I22,0) -> 0 | Q22: =IFERROR(ROUND('Project Managers'!I22/'Project Managers'!E22,4),0) -> 1 | R22: {=IF(ISBLANK('Project Managers'!AP22),IF('Project Managers'!I22<>0,('Project Managers'!I22-'Project Managers'!J22)/'Project Managers'!I22,'Project Managers'!AS22),'Project Managers'!AP22)} -> 0.05 | S22: 0.018 | T22: 0.01 | U22: =IFERROR(-('Project Managers'!I22-('Project Managers'!J22/(1-'Project Managers'!R22))),0) -> 58050.927 | V22: 6070.7358 | W22: =IFERROR(-('Project Managers'!I22-('Project Managers'!J22/(1-'Project Managers'!T22))),0) -> -4290.3959 | X22: =IFERROR(IF('Project Managers'!AQ22="",1,'Project Managers'!AQ22),0) -> 1 | Y22: 1 | Z22: 1 | AA22: =IFERROR(IF('Project Managers'!Z22='Project Managers'!Q22,0,(('Project Managers'!Z22*'Project Managers'!E22)-'Project Managers'!I22)),0) -> 0 | AB22: =IFERROR(IF('Project Managers'!Z22='Project Managers'!Q22,0,('Project Managers'!AA22-('Project Managers'!AA22*'Project Managers'!L22))),0) -> 0 | AC22: =IFERROR('Project Managers'!AA22-'Project Managers'!AB22,0) -> 0 | AD22: =IFERROR('Project Managers'!AC22/'Project Managers'!AA22,0) -> 0 | AE22: =IFERROR(IF('Project Managers'!Z22<1,1,0),0) -> 0 | AF22: =IFERROR(IF('Project Managers'!AE22=0,0,('Project Managers'!AE22*'Project Managers'!E22)-'Project Managers'!I22-'Project Managers'!AA22),0) -> 0 | AG22: =IFERROR(IF('Project Managers'!AE22='Project Managers'!V22,0,('Project Managers'!AF22-('Project Managers'!AF22*'Project Managers'!L22))),0) -> 0 | AH22: =IFERROR('Project Managers'!AF22-'Project Managers'!AG22,0) -> 0 | AI22: =IFERROR('Project Managers'!AH22/'Project Managers'!AF22,0) -> 0 | AK22: =IFERROR(IF('Project Managers'!AJ22=0,0,('Project Managers'!AJ22*'Project Managers'!E22)-'Project Managers'!I22-'Project Managers'!AA22-'Project Managers'!AF22),0) -> 0 | AL22: =IFERROR(IF('Project Managers'!AJ22='Project Managers'!V22,0,('Project Managers'!AK22-('Project Managers'!AK22*'Project Managers'!L22))),0) -> 0 | AM22: =IFERROR('Project Managers'!AK22-'Project Managers'!AL22,0) -> 0 | AN22: =IFERROR('Project Managers'!AM22/'Project Managers'!AK22,0) -> 0 | AO22: 0.22 | AP22: 0.05 | AS22: 0.06
B23: K HERNANDEZ | C23: 718000 | D23: TFC PARK 35 | E23: 4093979.3 | F23: =IFERROR('Project Managers'!E23*(1-'Project Managers'!H23),0) -> 3398002.8 | G23: =IFERROR('Project Managers'!E23-'Project Managers'!F23,0) -> 695976.48 | H23: {=IF(ISBLANK('Project Managers'!AO23),'Project Managers'!R23,'Project Managers'!AO23)} -> 0.17 | I23: 4093633.3 | J23: 3313579.7 | K23: =IFERROR('Project Managers'!I23-'Project Managers'!J23,0) -> 780053.59 | L23: =IFERROR('Project Managers'!K23/'Project Managers'!I23,0) -> 0.19055287 | M23: 4093633.3 | N23: =IFERROR(IF('Project Managers'!M23-'Project Managers'!I23>0,'Project Managers'!M23-'Project Managers'!I23,0),0) -> 0 | O23: =IFERROR(IF('Project Managers'!M23-'Project Managers'!I23<0,'Project Managers'!M23-'Project Managers'!I23,0),0) -> 0 | P23: =IFERROR('Project Managers'!E23-'Project Managers'!I23,0) -> 346 | Q23: =IFERROR(ROUND('Project Managers'!I23/'Project Managers'!E23,4),0) -> 0.9999 | R23: {=IF(ISBLANK('Project Managers'!AP23),IF('Project Managers'!I23<>0,('Project Managers'!I23-'Project Managers'!J23)/'Project Managers'!I23,'Project Managers'!AS23),'Project Managers'!AP23)} -> 0.19 | S23: 0.19 | T23: 0.19 | U23: =IFERROR(-('Project Managers'!I23-('Project Managers'!J23/(1-'Project Managers'!R23))),0) -> -2794.1472 | V23: -5913.4805 | W23: =IFERROR(-('Project Managers'!I23-('Project Managers'!J23/(1-'Project Managers'!T23))),0) -> -2794.1472 | X23: =IFERROR(IF('Project Managers'!AQ23="",1,'Project Managers'!AQ23),0) -> 1 | Y23: 1 | Z23: 1 | AA23: =IFERROR(IF('Project Managers'!Z23='Project Managers'!Q23,0,(('Project Managers'!Z23*'Project Managers'!E23)-'Project Managers'!I23)),0) -> 346 | AB23: =IFERROR(IF('Project Managers'!Z23='Project Managers'!Q23,0,('Project Managers'!AA23-('Project Managers'!AA23*'Project Managers'!L23))),0) -> 280.06871 | AC23: =IFERROR('Project Managers'!AA23-'Project Managers'!AB23,0) -> 65.931294 | AD23: =IFERROR('Project Managers'!AC23/'Project Managers'!AA23,0) -> 0.19055287 | AE23: =IFERROR(IF('Project Managers'!Z23<1,1,0),0) -> 0 | AF23: =IFERROR(IF('Project Managers'!AE23=0,0,('Project Managers'!AE23*'Project Managers'!E23)-'Project Managers'!I23-'Project Managers'!AA23),0) -> 0 | AG23: =IFERROR(IF('Project Managers'!AE23='Project Managers'!V23,0,('Project Managers'!AF23-('Project Managers'!AF23*'Project Managers'!L23))),0) -> 0 | AH23: =IFERROR('Project Managers'!AF23-'Project Managers'!AG23,0) -> 0 | AI23: =IFERROR('Project Managers'!AH23/'Project Managers'!AF23,0) -> 0 | AK23: =IFERROR(IF('Project Managers'!AJ23=0,0,('Project Managers'!AJ23*'Project Managers'!E23)-'Project Managers'!I23-'Project Managers'!AA23-'Project Managers'!AF23),0) -> 0 | AL23: =IFERROR(IF('Project Managers'!AJ23='Project Managers'!V23,0,('Project Managers'!AK23-('Project Managers'!AK23*'Project Managers'!L23))),0) -> 0 | AM23: =IFERROR('Project Managers'!AK23-'Project Managers'!AL23,0) -> 0 | AN23: =IFERROR('Project Managers'!AM23/'Project Managers'!AK23,0) -> 0 | AO23: 0.17 | AP23: 0.19 | AS23: 0.22
B24: K HERNANDEZ | C24: 720900 | D24: TFC GMP4 - BP4- DHNP RENO | E24: 7230488.5 | F24: =IFERROR('Project Managers'!E24*(1-'Project Managers'!H24),0) -> 6001305.5 | G24: =IFERROR('Project Managers'!E24-'Project Managers'!F24,0) -> 1229183.1 | H24: {=IF(ISBLANK('Project Managers'!AO24),'Project Managers'!R24,'Project Managers'!AO24)} -> 0.17 | I24: 5396691.7 | J24: 4063773.8 | K24: =IFERROR('Project Managers'!I24-'Project Managers'!J24,0) -> 1332917.9 | L24: =IFERROR('Project Managers'!K24/'Project Managers'!I24,0) -> 0.24698797 | M24: 6079333.9 | N24: =IFERROR(IF('Project Managers'!M24-'Project Managers'!I24>0,'Project Managers'!M24-'Project Managers'!I24,0),0) -> 682642.21 | O24: =IFERROR(IF('Project Managers'!M24-'Project Managers'!I24<0,'Project Managers'!M24-'Project Managers'!I24,0),0) -> 0 | P24: =IFERROR('Project Managers'!E24-'Project Managers'!I24,0) -> 1833796.8 | Q24: =IFERROR(ROUND('Project Managers'!I24/'Project Managers'!E24,4),0) -> 0.7464 | R24: {=IF(ISBLANK('Project Managers'!AP24),IF('Project Managers'!I24<>0,('Project Managers'!I24-'Project Managers'!J24)/'Project Managers'!I24,'Project Managers'!AS24),'Project Managers'!AP24)} -> 0.33 | S24: 0.26 | T24: 0.25 | U24: =IFERROR(-('Project Managers'!I24-('Project Managers'!J24/(1-'Project Managers'!R24))),0) -> 668642.31 | V24: 346109.89 | W24: =IFERROR(-('Project Managers'!I24-('Project Managers'!J24/(1-'Project Managers'!T24))),0) -> 21673.353 | X24: =IFERROR(IF('Project Managers'!AQ24="",1,'Project Managers'!AQ24),0) -> 1 | Y24: 0.971 | Z24: 0.95 | AA24: =IFERROR(IF('Project Managers'!Z24='Project Managers'!Q24,0,(('Project Managers'!Z24*'Project Managers'!E24)-'Project Managers'!I24)),0) -> 1472272.4 | AB24: =IFERROR(IF('Project Managers'!Z24='Project Managers'!Q24,0,('Project Managers'!AA24-('Project Managers'!AA24*'Project Managers'!L24))),0) -> 1108638.8 | AC24: =IFERROR('Project Managers'!AA24-'Project Managers'!AB24,0) -> 363633.57 | AD24: =IFERROR('Project Managers'!AC24/'Project Managers'!AA24,0) -> 0.24698797 | AE24: =IFERROR(IF('Project Managers'!Z24<1,1,0),0) -> 1 | AF24: =IFERROR(IF('Project Managers'!AE24=0,0,('Project Managers'!AE24*'Project Managers'!E24)-'Project Managers'!I24-'Project Managers'!AA24),0) -> 361524.43 | AG24: =IFERROR(IF('Project Managers'!AE24='Project Managers'!V24,0,('Project Managers'!AF24-('Project Managers'!AF24*'Project Managers'!L24))),0) -> 272232.24 | AH24: =IFERROR('Project Managers'!AF24-'Project Managers'!AG24,0) -> 89292.183 | AI24: =IFERROR('Project Managers'!AH24/'Project Managers'!AF24,0) -> 0.24698797 | AK24: =IFERROR(IF('Project Managers'!AJ24=0,0,('Project Managers'!AJ24*'Project Managers'!E24)-'Project Managers'!I24-'Project Managers'!AA24-'Project Managers'!AF24),0) -> 0 | AL24: =IFERROR(IF('Project Managers'!AJ24='Project Managers'!V24,0,('Project Managers'!AK24-('Project Managers'!AK24*'Project Managers'!L24))),0) -> 0 | AM24: =IFERROR('Project Managers'!AK24-'Project Managers'!AL24,0) -> 0 | AN24: =IFERROR('Project Managers'!AM24/'Project Managers'!AK24,0) -> 0 | AO24: 0.17 | AP24: 0.33 | AS24: 0.241
B25: K HERNANDEZ | C25: 722420 | D25: UT MAIN BLDG RESTORATION | E25: 3751721 | F25: =IFERROR('Project Managers'!E25*(1-'Project Managers'!H25),0) -> 3100595.9 | G25: =IFERROR('Project Managers'!E25-'Project Managers'!F25,0) -> 651125.11 | H25: {=IF(ISBLANK('Project Managers'!AO25),'Project Managers'!R25,'Project Managers'!AO25)} -> 0.17355371 | I25: 1327737.1 | J25: 1097303.4 | K25: =IFERROR('Project Managers'!I25-'Project Managers'!J25,0) -> 230433.7 | L25: =IFERROR('Project Managers'!K25/'Project Managers'!I25,0) -> 0.17355371 | M25: 1172929 | N25: =IFERROR(IF('Project Managers'!M25-'Project Managers'!I25>0,'Project Managers'!M25-'Project Managers'!I25,0),0) -> 0 | O25: =IFERROR(IF('Project Managers'!M25-'Project Managers'!I25<0,'Project Managers'!M25-'Project Managers'!I25,0),0) -> -154808.07 | P25: =IFERROR('Project Managers'!E25-'Project Managers'!I25,0) -> 2423983.9 | Q25: =IFERROR(ROUND('Project Managers'!I25/'Project Managers'!E25,4),0) -> 0.3539 | R25: =IF(ISBLANK('Project Managers'!AP25),IF('Project Managers'!I25<>0,('Project Managers'!I25-'Project Managers'!J25)/'Project Managers'!I25,'Project Managers'!AS25),'Project Managers'!AP25) -> 0.17355371 | S25: 0.17 | T25: 0.17 | U25: =IFERROR(-('Project Managers'!I25-('Project Managers'!J25/(1-'Project Managers'!R25))),0) -> 0 | V25: -5191.8275 | W25: =IFERROR(-('Project Managers'!I25-('Project Managers'!J25/(1-'Project Managers'!T25))),0) -> -5684.817 | X25: =IFERROR(IF('Project Managers'!AQ25="",1,'Project Managers'!AQ25),0) -> 1 | Y25: 0.5262 | Z25: 0.4 | AA25: =IFERROR(IF('Project Managers'!Z25='Project Managers'!Q25,0,(('Project Managers'!Z25*'Project Managers'!E25)-'Project Managers'!I25)),0) -> 172951.33 | AB25: =IFERROR(IF('Project Managers'!Z25='Project Managers'!Q25,0,('Project Managers'!AA25-('Project Managers'!AA25*'Project Managers'!L25))),0) -> 142934.98 | AC25: =IFERROR('Project Managers'!AA25-'Project Managers'!AB25,0) -> 30016.346 | AD25: =IFERROR('Project Managers'!AC25/'Project Managers'!AA25,0) -> 0.17355371 | AE25: =IFERROR(IF('Project Managers'!Z25<1,1,0),0) -> 1 | AF25: =IFERROR(IF('Project Managers'!AE25=0,0,('Project Managers'!AE25*'Project Managers'!E25)-'Project Managers'!I25-'Project Managers'!AA25),0) -> 2251032.6 | AG25: =IFERROR(IF('Project Managers'!AE25='Project Managers'!V25,0,('Project Managers'!AF25-('Project Managers'!AF25*'Project Managers'!L25))),0) -> 1860357.5 | AH25: =IFERROR('Project Managers'!AF25-'Project Managers'!AG25,0) -> 390675.07 | AI25: =IFERROR('Project Managers'!AH25/'Project Managers'!AF25,0) -> 0.17355371 | AK25: =IFERROR(IF('Project Managers'!AJ25=0,0,('Project Managers'!AJ25*'Project Managers'!E25)-'Project Managers'!I25-'Project Managers'!AA25-'Project Managers'!AF25),0) -> 0 | AL25: =IFERROR(IF('Project Managers'!AJ25='Project Managers'!V25,0,('Project Managers'!AK25-('Project Managers'!AK25*'Project Managers'!L25))),0) -> 0 | AM25: =IFERROR('Project Managers'!AK25-'Project Managers'!AL25,0) -> 0 | AN25: =IFERROR('Project Managers'!AM25/'Project Managers'!AK25,0) -> 0 | AS25: 0.174
B26: Subtotal of K HERNANDEZ | C26: - | D26: - | E26: =SUBTOTAL(9,E22:E25) -> 16561086 | F26: =SUBTOTAL(9,F22:F25) -> 13658124 | G26: =SUBTOTAL(9,G22:G25) -> 2902961.9 | H26: {=IF(ISBLANK('Project Managers'!AO26),'Project Managers'!R26,'Project Managers'!AO26)} -> - | I26: =SUBTOTAL(9,I22:I25) -> 12302959 | J26: =SUBTOTAL(9,J22:J25) -> 9940457.2 | K26: =SUBTOTAL(9,K22:K25) -> 2362501.7 | L26: =IFERROR('Project Managers'!K26/'Project Managers'!I26,0) -> 0.19202711 | M26: =SUBTOTAL(9,M22:M25) -> 12830793 | N26: =SUBTOTAL(9,N22:N25) -> 682642.21 | O26: =SUBTOTAL(9,O22:O25) -> -154808.07 | P26: =SUBTOTAL(9,P22:P25) -> 4258126.8 | Q26: =IFERROR(ROUND('Project Managers'!I26/'Project Managers'!E26,4),0) -> 0.7429 | R26: - | S26: - | T26: - | U26: =SUBTOTAL(9,U22:U25) -> 723899.09 | V26: =SUBTOTAL(9,V22:V25) -> 341075.32 | W26: =SUBTOTAL(9,W22:W25) -> 8903.9933 | X26: - | Y26: - | Z26: - | AA26: =SUBTOTAL(9,AA22:AA25) -> 1645569.7 | AB26: =SUBTOTAL(9,AB22:AB25) -> 1251853.9 | AC26: =IFERROR('Project Managers'!AA26-'Project Managers'!AB26,0) -> 393715.85 | AD26: =IFERROR('Project Managers'!AC26/'Project Managers'!AA26,0) -> 0.23925807 | AE26: =IFERROR(IF('Project Managers'!Z26<1,1,0),0) -> 0 | AF26: =SUBTOTAL(9,AF22:AF25) -> 2612557 | AG26: =SUBTOTAL(9,AG22:AG25) -> 2132589.8 | AH26: =SUBTOTAL(9,AH22:AH25) -> 479967.25 | AI26: =IFERROR('Project Managers'!AH26/'Project Managers'!AF26,0) -> 0.18371551 | AJ26: - | AK26: =SUBTOTAL(9,AK22:AK25) -> 0 | AL26: =SUBTOTAL(9,AL22:AL25) -> 0 | AM26: =SUBTOTAL(9,AM22:AM25) -> 0 | AN26: =IFERROR('Project Managers'!AM26/'Project Managers'!AK26,0) -> 0 | AO26: - | AP26: - | AQ26: - | AR26: - | AS26: -
B27: M CASELLA | C27: 722280 | D27: HUTTO 1 INITIAL IMPROV | E27: 13617357 | F27: =IFERROR('Project Managers'!E27*(1-'Project Managers'!H27),0) -> 11438580 | G27: =IFERROR('Project Managers'!E27-'Project Managers'!F27,0) -> 2178777.1 | H27: {=IF(ISBLANK('Project Managers'!AO27),'Project Managers'!R27,'Project Managers'!AO27)} -> 0.16 | I27: 13617357 | J27: 12370710 | K27: =IFERROR('Project Managers'!I27-'Project Managers'!J27,0) -> 1246647.3 | L27: =IFERROR('Project Managers'!K27/'Project Managers'!I27,0) -> 0.091548405 | M27: 13617357 | N27: =IFERROR(IF('Project Managers'!M27-'Project Managers'!I27>0,'Project Managers'!M27-'Project Managers'!I27,0),0) -> 0 | O27: =IFERROR(IF('Project Managers'!M27-'Project Managers'!I27<0,'Project Managers'!M27-'Project Managers'!I27,0),0) -> 0 | P27: =IFERROR('Project Managers'!E27-'Project Managers'!I27,0) -> 0 | Q27: =IFERROR(ROUND('Project Managers'!I27/'Project Managers'!E27,4),0) -> 1 | R27: {=IF(ISBLANK('Project Managers'!AP27),IF('Project Managers'!I27<>0,('Project Managers'!I27-'Project Managers'!J27)/'Project Managers'!I27,'Project Managers'!AS27),'Project Managers'!AP27)} -> 0.23 | S27: 0.09 | T27: 0.085 | U27: =IFERROR(-('Project Managers'!I27-('Project Managers'!J27/(1-'Project Managers'!R27))),0) -> 2448499.7 | V27: -143371.43 | W27: =IFERROR(-('Project Managers'!I27-('Project Managers'!J27/(1-'Project Managers'!T27))),0) -> -97455.699 | X27: =IFERROR(IF('Project Managers'!AQ27="",1,'Project Managers'!AQ27),0) -> 1 | Y27: 1 | Z27: 1 | AA27: =IFERROR(IF('Project Managers'!Z27='Project Managers'!Q27,0,(('Project Managers'!Z27*'Project Managers'!E27)-'Project Managers'!I27)),0) -> 0 | AB27: =IFERROR(IF('Project Managers'!Z27='Project Managers'!Q27,0,('Project Managers'!AA27-('Project Managers'!AA27*'Project Managers'!L27))),0) -> 0 | AC27: =IFERROR('Project Managers'!AA27-'Project Managers'!AB27,0) -> 0 | AD27: =IFERROR('Project Managers'!AC27/'Project Managers'!AA27,0) -> 0 | AE27: =IFERROR(IF('Project Managers'!Z27<1,1,0),0) -> 0 | AF27: =IFERROR(IF('Project Managers'!AE27=0,0,('Project Managers'!AE27*'Project Managers'!E27)-'Project Managers'!I27-'Project Managers'!AA27),0) -> 0 | AG27: =IFERROR(IF('Project Managers'!AE27='Project Managers'!V27,0,('Project Managers'!AF27-('Project Managers'!AF27*'Project Managers'!L27))),0) -> 0 | AH27: =IFERROR('Project Managers'!AF27-'Project Managers'!AG27,0) -> 0 | AI27: =IFERROR('Project Managers'!AH27/'Project Managers'!AF27,0) -> 0 | AK27: =IFERROR(IF('Project Managers'!AJ27=0,0,('Project Managers'!AJ27*'Project Managers'!E27)-'Project Managers'!I27-'Project Managers'!AA27-'Project Managers'!AF27),0) -> 0 | AL27: =IFERROR(IF('Project Managers'!AJ27='Project Managers'!V27,0,('Project Managers'!AK27-('Project Managers'!AK27*'Project Managers'!L27))),0) -> 0 | AM27: =IFERROR('Project Managers'!AK27-'Project Managers'!AL27,0) -> 0 | AN27: =IFERROR('Project Managers'!AM27/'Project Managers'!AK27,0) -> 0 | AO27: 0.16 | AP27: 0.23 | AS27: 0.1
B28: M CASELLA | C28: 722340 | D28: DEL VALLE LIBRARY | E28: 1188326 | F28: =IFERROR('Project Managers'!E28*(1-'Project Managers'!H28),0) -> 986310.58 | G28: =IFERROR('Project Managers'!E28-'Project Managers'!F28,0) -> 202015.42 | H28: {=IF(ISBLANK('Project Managers'!AO28),'Project Managers'!R28,'Project Managers'!AO28)} -> 0.17 | I28: 364066.55 | J28: 316579.52 | K28: =IFERROR('Project Managers'!I28-'Project Managers'!J28,0) -> 47487.03 | L28: =IFERROR('Project Managers'!K28/'Project Managers'!I28,0) -> 0.13043503 | M28: 259600 | N28: =IFERROR(IF('Project Managers'!M28-'Project Managers'!I28>0,'Project Managers'!M28-'Project Managers'!I28,0),0) -> 0 | O28: =IFERROR(IF('Project Managers'!M28-'Project Managers'!I28<0,'Project Managers'!M28-'Project Managers'!I28,0),0) -> -104466.55 | P28: =IFERROR('Project Managers'!E28-'Project Managers'!I28,0) -> 824259.45 | Q28: =IFERROR(ROUND('Project Managers'!I28/'Project Managers'!E28,4),0) -> 0.3064 | R28: {=IF(ISBLANK('Project Managers'!AP28),IF('Project Managers'!I28<>0,('Project Managers'!I28-'Project Managers'!J28)/'Project Managers'!I28,'Project Managers'!AS28),'Project Managers'!AP28)} -> 0.18 | S28: 0.12 | T28: 0.13 | U28: =IFERROR(-('Project Managers'!I28-('Project Managers'!J28/(1-'Project Managers'!R28))),0) -> 22006.035 | V28: -3314.9436 | W28: =IFERROR(-('Project Managers'!I28-('Project Managers'!J28/(1-'Project Managers'!T28))),0) -> -182.04425 | X28: =IFERROR(IF('Project Managers'!AQ28="",1,'Project Managers'!AQ28),0) -> 1 | Y28: 0.4647 | Z28: 0.3 | AA28: =IFERROR(IF('Project Managers'!Z28='Project Managers'!Q28,0,(('Project Managers'!Z28*'Project Managers'!E28)-'Project Managers'!I28)),0) -> -7568.75 | AB28: =IFERROR(IF('Project Managers'!Z28='Project Managers'!Q28,0,('Project Managers'!AA28-('Project Managers'!AA28*'Project Managers'!L28))),0) -> -6581.5199 | AC28: =IFERROR('Project Managers'!AA28-'Project Managers'!AB28,0) -> -987.2301 | AD28: =IFERROR('Project Managers'!AC28/'Project Managers'!AA28,0) -> 0.13043503 | AE28: =IFERROR(IF('Project Managers'!Z28<1,1,0),0) -> 1 | AF28: =IFERROR(IF('Project Managers'!AE28=0,0,('Project Managers'!AE28*'Project Managers'!E28)-'Project Managers'!I28-'Project Managers'!AA28),0) -> 831828.2 | AG28: =IFERROR(IF('Project Managers'!AE28='Project Managers'!V28,0,('Project Managers'!AF28-('Project Managers'!AF28*'Project Managers'!L28))),0) -> 723328.67 | AH28: =IFERROR('Project Managers'!AF28-'Project Managers'!AG28,0) -> 108499.53 | AI28: =IFERROR('Project Managers'!AH28/'Project Managers'!AF28,0) -> 0.13043503 | AK28: =IFERROR(IF('Project Managers'!AJ28=0,0,('Project Managers'!AJ28*'Project Managers'!E28)-'Project Managers'!I28-'Project Managers'!AA28-'Project Managers'!AF28),0) -> 0 | AL28: =IFERROR(IF('Project Managers'!AJ28='Project Managers'!V28,0,('Project Managers'!AK28-('Project Managers'!AK28*'Project Managers'!L28))),0) -> 0 | AM28: =IFERROR('Project Managers'!AK28-'Project Managers'!AL28,0) -> 0 | AN28: =IFERROR('Project Managers'!AM28/'Project Managers'!AK28,0) -> 0 | AO28: 0.17 | AP28: 0.18 | AS28: 0.13
B29: M CASELLA | C29: 722470 | D29: TSTC HUTTO | E29: 585596.97 | F29: =IFERROR('Project Managers'!E29*(1-'Project Managers'!H29),0) -> 485972.57 | G29: =IFERROR('Project Managers'!E29-'Project Managers'!F29,0) -> 99624.395 | H29: {=IF(ISBLANK('Project Managers'!AO29),'Project Managers'!R29,'Project Managers'!AO29)} -> 0.17012451 | I29: 177100 | J29: 146970.95 | K29: =IFERROR('Project Managers'!I29-'Project Managers'!J29,0) -> 30129.05 | L29: =IFERROR('Project Managers'!K29/'Project Managers'!I29,0) -> 0.17012451 | M29: 398194.97 | N29: =IFERROR(IF('Project Managers'!M29-'Project Managers'!I29>0,'Project Managers'!M29-'Project Managers'!I29,0),0) -> 221094.97 | O29: =IFERROR(IF('Project Managers'!M29-'Project Managers'!I29<0,'Project Managers'!M29-'Project Managers'!I29,0),0) -> 0 | P29: =IFERROR('Project Managers'!E29-'Project Managers'!I29,0) -> 408496.97 | Q29: =IFERROR(ROUND('Project Managers'!I29/'Project Managers'!E29,4),0) -> 0.3024 | R29: =IF(ISBLANK('Project Managers'!AP29),IF('Project Managers'!I29<>0,('Project Managers'!I29-'Project Managers'!J29)/'Project Managers'!I29,'Project Managers'!AS29),'Project Managers'!AP29) -> 0.17012451 | S29: 0.17 | T29: 0.17 | U29: =IFERROR(-('Project Managers'!I29-('Project Managers'!J29/(1-'Project Managers'!R29))),0) -> 0 | V29: -25.994337 | W29: =IFERROR(-('Project Managers'!I29-('Project Managers'!J29/(1-'Project Managers'!T29))),0) -> -26.566265 | X29: =IFERROR(IF('Project Managers'!AQ29="",1,'Project Managers'!AQ29),0) -> 1 | Y29: 0.648 | Z29: 0.9 | AA29: =IFERROR(IF('Project Managers'!Z29='Project Managers'!Q29,0,(('Project Managers'!Z29*'Project Managers'!E29)-'Project Managers'!I29)),0) -> 349937.27 | AB29: =IFERROR(IF('Project Managers'!Z29='Project Managers'!Q29,0,('Project Managers'!AA29-('Project Managers'!AA29*'Project Managers'!L29))),0) -> 290404.37 | AC29: =IFERROR('Project Managers'!AA29-'Project Managers'!AB29,0) -> 59532.906 | AD29: =IFERROR('Project Managers'!AC29/'Project Managers'!AA29,0) -> 0.17012451 | AE29: =IFERROR(IF('Project Managers'!Z29<1,1,0),0) -> 1 | AF29: =IFERROR(IF('Project Managers'!AE29=0,0,('Project Managers'!AE29*'Project Managers'!E29)-'Project Managers'!I29-'Project Managers'!AA29),0) -> 58559.697 | AG29: =IFERROR(IF('Project Managers'!AE29='Project Managers'!V29,0,('Project Managers'!AF29-('Project Managers'!AF29*'Project Managers'!L29))),0) -> 48597.257 | AH29: =IFERROR('Project Managers'!AF29-'Project Managers'!AG29,0) -> 9962.4395 | AI29: =IFERROR('Project Managers'!AH29/'Project Managers'!AF29,0) -> 0.17012451 | AK29: =IFERROR(IF('Project Managers'!AJ29=0,0,('Project Managers'!AJ29*'Project Managers'!E29)-'Project Managers'!I29-'Project Managers'!AA29-'Project Managers'!AF29),0) -> 0 | AL29: =IFERROR(IF('Project Managers'!AJ29='Project Managers'!V29,0,('Project Managers'!AK29-('Project Managers'!AK29*'Project Managers'!L29))),0) -> 0 | AM29: =IFERROR('Project Managers'!AK29-'Project Managers'!AL29,0) -> 0 | AN29: =IFERROR('Project Managers'!AM29/'Project Managers'!AK29,0) -> 0 | AS29: 0.17
B30: Subtotal of M CASELLA | C30: - | D30: - | E30: =SUBTOTAL(9,E27:E29) -> 15391280 | F30: =SUBTOTAL(9,F27:F29) -> 12910863 | G30: =SUBTOTAL(9,G27:G29) -> 2480416.9 | H30: {=IF(ISBLANK('Project Managers'!AO30),'Project Managers'!R30,'Project Managers'!AO30)} -> - | I30: =SUBTOTAL(9,I27:I29) -> 14158524 | J30: =SUBTOTAL(9,J27:J29) -> 12834260 | K30: =SUBTOTAL(9,K27:K29) -> 1324263.4 | L30: =IFERROR('Project Managers'!K30/'Project Managers'!I30,0) -> 0.093531178 | M30: =SUBTOTAL(9,M27:M29) -> 14275152 | N30: =SUBTOTAL(9,N27:N29) -> 221094.97 | O30: =SUBTOTAL(9,O27:O29) -> -104466.55 | P30: =SUBTOTAL(9,P27:P29) -> 1232756.4 | Q30: =IFERROR(ROUND('Project Managers'!I30/'Project Managers'!E30,4),0) -> 0.9199 | R30: - | S30: - | T30: - | U30: =SUBTOTAL(9,U27:U29) -> 2470505.8 | V30: =SUBTOTAL(9,V27:V29) -> -146712.37 | W30: =SUBTOTAL(9,W27:W29) -> -97664.31 | X30: - | Y30: - | Z30: - | AA30: =SUBTOTAL(9,AA27:AA29) -> 342368.52 | AB30: =SUBTOTAL(9,AB27:AB29) -> 283822.85 | AC30: =IFERROR('Project Managers'!AA30-'Project Managers'!AB30,0) -> 58545.676 | AD30: =IFERROR('Project Managers'!AC30/'Project Managers'!AA30,0) -> 0.17100192 | AE30: =IFERROR(IF('Project Managers'!Z30<1,1,0),0) -> 0 | AF30: =SUBTOTAL(9,AF27:AF29) -> 890387.9 | AG30: =SUBTOTAL(9,AG27:AG29) -> 771925.92 | AH30: =SUBTOTAL(9,AH27:AH29) -> 118461.97 | AI30: =IFERROR('Project Managers'!AH30/'Project Managers'!AF30,0) -> 0.13304535 | AJ30: - | AK30: =SUBTOTAL(9,AK27:AK29) -> 0 | AL30: =SUBTOTAL(9,AL27:AL29) -> 0 | AM30: =SUBTOTAL(9,AM27:AM29) -> 0 | AN30: =IFERROR('Project Managers'!AM30/'Project Managers'!AK30,0) -> 0 | AO30: - | AP30: - | AQ30: - | AR30: - | AS30: -
B31: T FERGUSON | C31: 718100 | D31: TESLA 2022 PLASTIC FEEDER | E31: 898831.39 | F31: =IFERROR('Project Managers'!E31*(1-'Project Managers'!H31),0) -> 728053.43 | G31: =IFERROR('Project Managers'!E31-'Project Managers'!F31,0) -> 170777.96 | H31: {=IF(ISBLANK('Project Managers'!AO31),'Project Managers'!R31,'Project Managers'!AO31)} -> 0.19 | I31: 898831.39 | J31: 744578.07 | K31: =IFERROR('Project Managers'!I31-'Project Managers'!J31,0) -> 154253.32 | L31: =IFERROR('Project Managers'!K31/'Project Managers'!I31,0) -> 0.17161541 | M31: 898831.39 | N31: =IFERROR(IF('Project Managers'!M31-'Project Managers'!I31>0,'Project Managers'!M31-'Project Managers'!I31,0),0) -> 0 | O31: =IFERROR(IF('Project Managers'!M31-'Project Managers'!I31<0,'Project Managers'!M31-'Project Managers'!I31,0),0) -> 0 | P31: =IFERROR('Project Managers'!E31-'Project Managers'!I31,0) -> 0 | Q31: =IFERROR(ROUND('Project Managers'!I31/'Project Managers'!E31,4),0) -> 1 | R31: {=IF(ISBLANK('Project Managers'!AP31),IF('Project Managers'!I31<>0,('Project Managers'!I31-'Project Managers'!J31)/'Project Managers'!I31,'Project Managers'!AS31),'Project Managers'!AP31)} -> 0.17 | S31: 0.08 | T31: 0.07 | U31: =IFERROR(-('Project Managers'!I31-('Project Managers'!J31/(1-'Project Managers'!R31))),0) -> -1749.378 | V31: -89507.401 | W31: =IFERROR(-('Project Managers'!I31-('Project Managers'!J31/(1-'Project Managers'!T31))),0) -> -98209.809 | X31: =IFERROR(IF('Project Managers'!AQ31="",1,'Project Managers'!AQ31),0) -> 1 | Y31: 1 | Z31: 1 | AA31: =IFERROR(IF('Project Managers'!Z31='Project Managers'!Q31,0,(('Project Managers'!Z31*'Project Managers'!E31)-'Project Managers'!I31)),0) -> 0 | AB31: =IFERROR(IF('Project Managers'!Z31='Project Managers'!Q31,0,('Project Managers'!AA31-('Project Managers'!AA31*'Project Managers'!L31))),0) -> 0 | AC31: =IFERROR('Project Managers'!AA31-'Project Managers'!AB31,0) -> 0 | AD31: =IFERROR('Project Managers'!AC31/'Project Managers'!AA31,0) -> 0 | AE31: =IFERROR(IF('Project Managers'!Z31<1,1,0),0) -> 0 | AF31: =IFERROR(IF('Project Managers'!AE31=0,0,('Project Managers'!AE31*'Project Managers'!E31)-'Project Managers'!I31-'Project Managers'!AA31),0) -> 0 | AG31: =IFERROR(IF('Project Managers'!AE31='Project Managers'!V31,0,('Project Managers'!AF31-('Project Managers'!AF31*'Project Managers'!L31))),0) -> 0 | AH31: =IFERROR('Project Managers'!AF31-'Project Managers'!AG31,0) -> 0 | AI31: =IFERROR('Project Managers'!AH31/'Project Managers'!AF31,0) -> 0 | AK31: =IFERROR(IF('Project Managers'!AJ31=0,0,('Project Managers'!AJ31*'Project Managers'!E31)-'Project Managers'!I31-'Project Managers'!AA31-'Project Managers'!AF31),0) -> 0 | AL31: =IFERROR(IF('Project Managers'!AJ31='Project Managers'!V31,0,('Project Managers'!AK31-('Project Managers'!AK31*'Project Managers'!L31))),0) -> 0 | AM31: =IFERROR('Project Managers'!AK31-'Project Managers'!AL31,0) -> 0 | AN31: =IFERROR('Project Managers'!AM31/'Project Managers'!AK31,0) -> 0 | AO31: 0.19 | AP31: 0.17
